2019-02-21 15:14:01,162 INFO org.apache.hadoop.yarn.server.resourcemanager.ResourceManager: STARTUP_MSG: 
/************************************************************
STARTUP_MSG: Starting ResourceManager
STARTUP_MSG:   user = anushamuppalla
STARTUP_MSG:   host = ANUSHAs-Air.kc.umkc.edu/10.205.2.163
STARTUP_MSG:   args = []
STARTUP_MSG:   version = 2.8.1
STARTUP_MSG:   build = https://git-wip-us.apache.org/repos/asf/hadoop.git -r 20fe5304904fc2f5a18053c389e43cd26f7a70fe; compiled by 'vinodkv' on 2017-06-02T06:14Z
STARTUP_MSG:   java = 11.0.2
************************************************************/
2019-02-21 15:14:01,232 INFO org.apache.hadoop.yarn.server.resourcemanager.ResourceManager: registered UNIX signal handlers for [TERM, HUP, INT]
2019-02-21 15:14:03,547 INFO org.apache.hadoop.conf.Configuration: found resource core-site.xml at file:/Users/anushamuppalla/hadoop-2.8.1/etc/hadoop/core-site.xml
2019-02-21 15:14:04,044 WARN org.apache.hadoop.util.NativeCodeLoader: Unable to load native-hadoop library for your platform... using builtin-java classes where applicable
2019-02-21 15:14:04,309 INFO org.apache.hadoop.security.Groups: clearing userToGroupsMap cache
2019-02-21 15:14:04,938 INFO org.apache.hadoop.conf.Configuration: found resource yarn-site.xml at file:/Users/anushamuppalla/hadoop-2.8.1/etc/hadoop/yarn-site.xml
2019-02-21 15:14:06,699 INFO org.apache.hadoop.yarn.event.AsyncDispatcher: Registering class org.apache.hadoop.yarn.server.resourcemanager.RMFatalEventType for class org.apache.hadoop.yarn.server.resourcemanager.ResourceManager$RMFatalEventDispatcher
2019-02-21 15:14:07,403 INFO org.apache.hadoop.yarn.server.resourcemanager.security.NMTokenSecretManagerInRM: NMTokenKeyRollingInterval: 86400000ms and NMTokenKeyActivationDelay: 900000ms
2019-02-21 15:14:07,444 INFO org.apache.hadoop.yarn.server.resourcemanager.security.RMContainerTokenSecretManager: ContainerTokenKeyRollingInterval: 86400000ms and ContainerTokenKeyActivationDelay: 900000ms
2019-02-21 15:14:07,462 INFO org.apache.hadoop.yarn.server.resourcemanager.security.AMRMTokenSecretManager: AMRMTokenKeyRollingInterval: 86400000ms and AMRMTokenKeyActivationDelay: 900000 ms
2019-02-21 15:14:07,638 INFO org.apache.hadoop.yarn.event.AsyncDispatcher: Registering class org.apache.hadoop.yarn.server.resourcemanager.recovery.RMStateStoreEventType for class org.apache.hadoop.yarn.server.resourcemanager.recovery.RMStateStore$ForwardingEventHandler
2019-02-21 15:14:07,651 INFO org.apache.hadoop.yarn.event.AsyncDispatcher: Registering class org.apache.hadoop.yarn.server.resourcemanager.NodesListManagerEventType for class org.apache.hadoop.yarn.server.resourcemanager.NodesListManager
2019-02-21 15:14:07,652 INFO org.apache.hadoop.yarn.server.resourcemanager.ResourceManager: Using Scheduler: org.apache.hadoop.yarn.server.resourcemanager.scheduler.capacity.CapacityScheduler
2019-02-21 15:14:07,808 INFO org.apache.hadoop.yarn.event.AsyncDispatcher: Registering class org.apache.hadoop.yarn.server.resourcemanager.scheduler.event.SchedulerEventType for class org.apache.hadoop.yarn.server.resourcemanager.ResourceManager$SchedulerEventDispatcher
2019-02-21 15:14:07,821 INFO org.apache.hadoop.yarn.event.AsyncDispatcher: Registering class org.apache.hadoop.yarn.server.resourcemanager.rmapp.RMAppEventType for class org.apache.hadoop.yarn.server.resourcemanager.ResourceManager$ApplicationEventDispatcher
2019-02-21 15:14:07,832 INFO org.apache.hadoop.yarn.event.AsyncDispatcher: Registering class org.apache.hadoop.yarn.server.resourcemanager.rmapp.attempt.RMAppAttemptEventType for class org.apache.hadoop.yarn.server.resourcemanager.ResourceManager$ApplicationAttemptEventDispatcher
2019-02-21 15:14:07,836 INFO org.apache.hadoop.yarn.event.AsyncDispatcher: Registering class org.apache.hadoop.yarn.server.resourcemanager.rmnode.RMNodeEventType for class org.apache.hadoop.yarn.server.resourcemanager.ResourceManager$NodeEventDispatcher
2019-02-21 15:14:08,241 INFO org.apache.hadoop.metrics2.impl.MetricsConfig: loaded properties from hadoop-metrics2.properties
2019-02-21 15:14:09,244 INFO org.apache.hadoop.metrics2.impl.MetricsSystemImpl: Scheduled Metric snapshot period at 10 second(s).
2019-02-21 15:14:09,244 INFO org.apache.hadoop.metrics2.impl.MetricsSystemImpl: ResourceManager metrics system started
2019-02-21 15:14:09,401 INFO org.apache.hadoop.yarn.event.AsyncDispatcher: Registering class org.apache.hadoop.yarn.server.resourcemanager.RMAppManagerEventType for class org.apache.hadoop.yarn.server.resourcemanager.RMAppManager
2019-02-21 15:14:09,433 INFO org.apache.hadoop.yarn.event.AsyncDispatcher: Registering class org.apache.hadoop.yarn.server.resourcemanager.amlauncher.AMLauncherEventType for class org.apache.hadoop.yarn.server.resourcemanager.amlauncher.ApplicationMasterLauncher
2019-02-21 15:14:09,443 INFO org.apache.hadoop.yarn.server.resourcemanager.RMNMInfo: Registered RMNMInfo MBean
2019-02-21 15:14:09,526 INFO org.apache.hadoop.yarn.security.YarnAuthorizationProvider: org.apache.hadoop.yarn.security.ConfiguredYarnAuthorizer is instiantiated.
2019-02-21 15:14:09,531 INFO org.apache.hadoop.util.HostsFileReader: Refreshing hosts (include/exclude) list
2019-02-21 15:14:09,571 INFO org.apache.hadoop.conf.Configuration: found resource capacity-scheduler.xml at file:/Users/anushamuppalla/hadoop-2.8.1/etc/hadoop/capacity-scheduler.xml
2019-02-21 15:14:10,027 INFO org.apache.hadoop.yarn.server.resourcemanager.scheduler.capacity.CapacitySchedulerConfiguration: max alloc mb per queue for root is undefined
2019-02-21 15:14:10,028 INFO org.apache.hadoop.yarn.server.resourcemanager.scheduler.capacity.CapacitySchedulerConfiguration: max alloc vcore per queue for root is undefined
2019-02-21 15:14:10,096 INFO org.apache.hadoop.yarn.server.resourcemanager.scheduler.capacity.ParentQueue: root, capacity=1.0, asboluteCapacity=1.0, maxCapacity=1.0, asboluteMaxCapacity=1.0, state=RUNNING, acls=SUBMIT_APP:*ADMINISTER_QUEUE:*, labels=*,, offswitchPerHeartbeatLimit = 1, reservationsContinueLooking=true
2019-02-21 15:14:10,096 INFO org.apache.hadoop.yarn.server.resourcemanager.scheduler.capacity.ParentQueue: Initialized parent-queue root name=root, fullname=root
2019-02-21 15:14:10,188 INFO org.apache.hadoop.yarn.server.resourcemanager.scheduler.capacity.CapacitySchedulerConfiguration: max alloc mb per queue for root.default is undefined
2019-02-21 15:14:10,188 INFO org.apache.hadoop.yarn.server.resourcemanager.scheduler.capacity.CapacitySchedulerConfiguration: max alloc vcore per queue for root.default is undefined
2019-02-21 15:14:10,205 INFO org.apache.hadoop.yarn.server.resourcemanager.scheduler.capacity.LeafQueue: Initializing default
capacity = 1.0 [= (float) configuredCapacity / 100 ]
asboluteCapacity = 1.0 [= parentAbsoluteCapacity * capacity ]
maxCapacity = 1.0 [= configuredMaxCapacity ]
absoluteMaxCapacity = 1.0 [= 1.0 maximumCapacity undefined, (parentAbsoluteMaxCapacity * maximumCapacity) / 100 otherwise ]
userLimit = 100 [= configuredUserLimit ]
userLimitFactor = 1.0 [= configuredUserLimitFactor ]
maxApplications = 10000 [= configuredMaximumSystemApplicationsPerQueue or (int)(configuredMaximumSystemApplications * absoluteCapacity)]
maxApplicationsPerUser = 10000 [= (int)(maxApplications * (userLimit / 100.0f) * userLimitFactor) ]
usedCapacity = 0.0 [= usedResourcesMemory / (clusterResourceMemory * absoluteCapacity)]
absoluteUsedCapacity = 0.0 [= usedResourcesMemory / clusterResourceMemory]
maxAMResourcePerQueuePercent = 0.1 [= configuredMaximumAMResourcePercent ]
minimumAllocationFactor = 0.875 [= (float)(maximumAllocationMemory - minimumAllocationMemory) / maximumAllocationMemory ]
maximumAllocation = <memory:8192, vCores:4> [= configuredMaxAllocation ]
numContainers = 0 [= currentNumContainers ]
state = RUNNING [= configuredState ]
acls = SUBMIT_APP:*ADMINISTER_QUEUE:* [= configuredAcls ]
nodeLocalityDelay = 40
labels=*,
reservationsContinueLooking = true
preemptionDisabled = true
defaultAppPriorityPerQueue = 0
2019-02-21 15:14:10,206 INFO org.apache.hadoop.yarn.server.resourcemanager.scheduler.capacity.CapacityScheduler: Initialized queue: default: capacity=1.0, absoluteCapacity=1.0, usedResources=<memory:0, vCores:0>, usedCapacity=0.0, absoluteUsedCapacity=0.0, numApps=0, numContainers=0
2019-02-21 15:14:10,207 INFO org.apache.hadoop.yarn.server.resourcemanager.scheduler.capacity.CapacityScheduler: Initialized queue: root: numChildQueue= 1, capacity=1.0, absoluteCapacity=1.0, usedResources=<memory:0, vCores:0>usedCapacity=0.0, numApps=0, numContainers=0
2019-02-21 15:14:10,210 INFO org.apache.hadoop.yarn.server.resourcemanager.scheduler.capacity.CapacityScheduler: Initialized root queue root: numChildQueue= 1, capacity=1.0, absoluteCapacity=1.0, usedResources=<memory:0, vCores:0>usedCapacity=0.0, numApps=0, numContainers=0
2019-02-21 15:14:10,210 INFO org.apache.hadoop.yarn.server.resourcemanager.scheduler.capacity.CapacityScheduler: Initialized queue mappings, override: false
2019-02-21 15:14:10,241 INFO org.apache.hadoop.yarn.server.resourcemanager.scheduler.capacity.CapacityScheduler: Initialized CapacityScheduler with calculator=class org.apache.hadoop.yarn.util.resource.DefaultResourceCalculator, minimumAllocation=<<memory:1024, vCores:1>>, maximumAllocation=<<memory:8192, vCores:4>>, asynchronousScheduling=false, asyncScheduleInterval=5ms
2019-02-21 15:14:10,267 INFO org.apache.hadoop.conf.Configuration: dynamic-resources.xml not found
2019-02-21 15:14:10,329 INFO org.apache.hadoop.yarn.server.resourcemanager.metrics.SystemMetricsPublisher: YARN system metrics publishing service is not enabled
2019-02-21 15:14:10,329 INFO org.apache.hadoop.yarn.server.resourcemanager.ResourceManager: Transitioning to active state
2019-02-21 15:14:10,386 INFO org.apache.hadoop.util.JvmPauseMonitor: Starting JVM pause monitor
2019-02-21 15:14:10,467 INFO org.apache.hadoop.yarn.server.resourcemanager.recovery.RMStateStore: Updating AMRMToken
2019-02-21 15:14:10,467 INFO org.apache.hadoop.yarn.server.resourcemanager.security.RMContainerTokenSecretManager: Rolling master-key for container-tokens
2019-02-21 15:14:10,468 INFO org.apache.hadoop.yarn.server.resourcemanager.security.NMTokenSecretManagerInRM: Rolling master-key for nm-tokens
2019-02-21 15:14:10,470 INFO org.apache.hadoop.security.token.delegation.AbstractDelegationTokenSecretManager: Updating the current master key for generating delegation tokens
2019-02-21 15:14:10,472 INFO org.apache.hadoop.yarn.server.resourcemanager.security.RMDelegationTokenSecretManager: storing master key with keyID 1
2019-02-21 15:14:10,473 INFO org.apache.hadoop.yarn.server.resourcemanager.recovery.RMStateStore: Storing RMDTMasterKey.
2019-02-21 15:14:10,477 INFO org.apache.hadoop.security.token.delegation.AbstractDelegationTokenSecretManager: Starting expired delegation token remover thread, tokenRemoverScanInterval=60 min(s)
2019-02-21 15:14:10,478 INFO org.apache.hadoop.security.token.delegation.AbstractDelegationTokenSecretManager: Updating the current master key for generating delegation tokens
2019-02-21 15:14:10,480 INFO org.apache.hadoop.yarn.server.resourcemanager.security.RMDelegationTokenSecretManager: storing master key with keyID 2
2019-02-21 15:14:10,481 INFO org.apache.hadoop.yarn.server.resourcemanager.recovery.RMStateStore: Storing RMDTMasterKey.
2019-02-21 15:14:10,500 INFO org.apache.hadoop.yarn.event.AsyncDispatcher: Registering class org.apache.hadoop.yarn.nodelabels.event.NodeLabelsStoreEventType for class org.apache.hadoop.yarn.nodelabels.CommonNodeLabelsManager$ForwardingEventHandler
2019-02-21 15:14:10,704 INFO org.apache.hadoop.ipc.CallQueueManager: Using callQueue: class java.util.concurrent.LinkedBlockingQueue queueCapacity: 5000 scheduler: class org.apache.hadoop.ipc.DefaultRpcScheduler
2019-02-21 15:14:10,928 INFO org.apache.hadoop.ipc.Server: Starting Socket Reader #1 for port 8031
2019-02-21 15:14:12,448 INFO org.apache.hadoop.yarn.factories.impl.pb.RpcServerFactoryPBImpl: Adding protocol org.apache.hadoop.yarn.server.api.ResourceTrackerPB to the server
2019-02-21 15:14:12,450 INFO org.apache.hadoop.ipc.Server: IPC Server Responder: starting
2019-02-21 15:14:12,452 INFO org.apache.hadoop.ipc.Server: IPC Server listener on 8031: starting
2019-02-21 15:14:12,589 INFO org.apache.hadoop.ipc.CallQueueManager: Using callQueue: class java.util.concurrent.LinkedBlockingQueue queueCapacity: 5000 scheduler: class org.apache.hadoop.ipc.DefaultRpcScheduler
2019-02-21 15:14:12,641 INFO org.apache.hadoop.ipc.Server: Starting Socket Reader #1 for port 8030
2019-02-21 15:14:12,733 INFO org.apache.hadoop.yarn.factories.impl.pb.RpcServerFactoryPBImpl: Adding protocol org.apache.hadoop.yarn.api.ApplicationMasterProtocolPB to the server
2019-02-21 15:14:12,734 INFO org.apache.hadoop.ipc.Server: IPC Server Responder: starting
2019-02-21 15:14:12,736 INFO org.apache.hadoop.ipc.Server: IPC Server listener on 8030: starting
2019-02-21 15:14:13,264 INFO org.apache.hadoop.ipc.CallQueueManager: Using callQueue: class java.util.concurrent.LinkedBlockingQueue queueCapacity: 5000 scheduler: class org.apache.hadoop.ipc.DefaultRpcScheduler
2019-02-21 15:14:13,267 INFO org.apache.hadoop.ipc.Server: Starting Socket Reader #1 for port 8032
2019-02-21 15:14:13,300 INFO org.apache.hadoop.yarn.factories.impl.pb.RpcServerFactoryPBImpl: Adding protocol org.apache.hadoop.yarn.api.ApplicationClientProtocolPB to the server
2019-02-21 15:14:13,310 INFO org.apache.hadoop.ipc.Server: IPC Server Responder: starting
2019-02-21 15:14:13,312 INFO org.apache.hadoop.ipc.Server: IPC Server listener on 8032: starting
2019-02-21 15:14:13,358 INFO org.apache.hadoop.yarn.server.resourcemanager.ResourceManager: Transitioned to active state
2019-02-21 15:14:13,899 INFO org.mortbay.log: Logging to org.slf4j.impl.Log4jLoggerAdapter(org.mortbay.log) via org.mortbay.log.Slf4jLog
2019-02-21 15:14:13,934 INFO org.apache.hadoop.security.authentication.server.AuthenticationFilter: Unable to initialize FileSignerSecretProvider, falling back to use random secrets.
2019-02-21 15:14:13,969 INFO org.apache.hadoop.http.HttpRequestLog: Http request log for http.requests.resourcemanager is not defined
2019-02-21 15:14:14,020 INFO org.apache.hadoop.http.HttpServer2: Added global filter 'safety' (class=org.apache.hadoop.http.HttpServer2$QuotingInputFilter)
2019-02-21 15:14:14,035 INFO org.apache.hadoop.http.HttpServer2: Added filter RMAuthenticationFilter (class=org.apache.hadoop.yarn.server.security.http.RMAuthenticationFilter) to context cluster
2019-02-21 15:14:14,036 INFO org.apache.hadoop.http.HttpServer2: Added filter RMAuthenticationFilter (class=org.apache.hadoop.yarn.server.security.http.RMAuthenticationFilter) to context logs
2019-02-21 15:14:14,036 INFO org.apache.hadoop.http.HttpServer2: Added filter RMAuthenticationFilter (class=org.apache.hadoop.yarn.server.security.http.RMAuthenticationFilter) to context static
2019-02-21 15:14:14,038 INFO org.apache.hadoop.http.HttpServer2: Added filter static_user_filter (class=org.apache.hadoop.http.lib.StaticUserWebFilter$StaticUserFilter) to context cluster
2019-02-21 15:14:14,038 INFO org.apache.hadoop.http.HttpServer2: Added filter static_user_filter (class=org.apache.hadoop.http.lib.StaticUserWebFilter$StaticUserFilter) to context logs
2019-02-21 15:14:14,039 INFO org.apache.hadoop.http.HttpServer2: Added filter static_user_filter (class=org.apache.hadoop.http.lib.StaticUserWebFilter$StaticUserFilter) to context static
2019-02-21 15:14:14,055 INFO org.apache.hadoop.http.HttpServer2: adding path spec: /cluster/*
2019-02-21 15:14:14,056 INFO org.apache.hadoop.http.HttpServer2: adding path spec: /ws/*
2019-02-21 15:14:16,711 INFO org.apache.hadoop.yarn.webapp.WebApps: Registered webapp guice modules
2019-02-21 15:14:16,737 INFO org.apache.hadoop.http.HttpServer2: Jetty bound to port 8088
2019-02-21 15:14:16,741 INFO org.mortbay.log: jetty-6.1.26
2019-02-21 15:14:16,958 INFO org.mortbay.log: Extract jar:file:/Users/anushamuppalla/hadoop-2.8.1/share/hadoop/yarn/hadoop-yarn-common-2.8.1.jar!/webapps/cluster to /var/folders/w5/msff5yg55hvgnrf5gxk_qk680000gn/T/Jetty_localhost_8088_cluster____.3j26f5/webapp
2019-02-21 15:14:17,574 INFO org.apache.hadoop.security.token.delegation.AbstractDelegationTokenSecretManager: Updating the current master key for generating delegation tokens
2019-02-21 15:14:17,578 INFO org.apache.hadoop.security.token.delegation.AbstractDelegationTokenSecretManager: Starting expired delegation token remover thread, tokenRemoverScanInterval=60 min(s)
2019-02-21 15:14:17,579 INFO org.apache.hadoop.security.token.delegation.AbstractDelegationTokenSecretManager: Updating the current master key for generating delegation tokens
2019-02-21 15:14:25,156 INFO org.mortbay.log: Started HttpServer2$SelectChannelConnectorWithSafeStartup@localhost:8088
2019-02-21 15:14:25,158 INFO org.apache.hadoop.yarn.webapp.WebApps: Web app cluster started at 8088
2019-02-21 15:14:25,365 INFO org.apache.hadoop.ipc.CallQueueManager: Using callQueue: class java.util.concurrent.LinkedBlockingQueue queueCapacity: 100 scheduler: class org.apache.hadoop.ipc.DefaultRpcScheduler
2019-02-21 15:14:25,368 INFO org.apache.hadoop.ipc.Server: Starting Socket Reader #1 for port 8033
2019-02-21 15:14:25,415 INFO org.apache.hadoop.yarn.factories.impl.pb.RpcServerFactoryPBImpl: Adding protocol org.apache.hadoop.yarn.server.api.ResourceManagerAdministrationProtocolPB to the server
2019-02-21 15:14:25,418 INFO org.apache.hadoop.ipc.Server: IPC Server Responder: starting
2019-02-21 15:14:25,418 INFO org.apache.hadoop.ipc.Server: IPC Server listener on 8033: starting
2019-02-21 15:14:27,099 INFO org.apache.hadoop.yarn.server.resourcemanager.ResourceTrackerService: NodeManager from node anushas-air.kc.umkc.edu(cmPort: 56045 httpPort: 8042) registered with capability: <memory:8192, vCores:8>, assigned nodeId anushas-air.kc.umkc.edu:56045
2019-02-21 15:14:27,119 INFO org.apache.hadoop.yarn.server.resourcemanager.rmnode.RMNodeImpl: anushas-air.kc.umkc.edu:56045 Node Transitioned from NEW to RUNNING
2019-02-21 15:14:27,152 INFO org.apache.hadoop.yarn.server.resourcemanager.scheduler.capacity.CapacityScheduler: Added node anushas-air.kc.umkc.edu:56045 clusterResource: <memory:8192, vCores:8>
2019-02-21 15:24:09,590 INFO org.apache.hadoop.yarn.server.resourcemanager.scheduler.AbstractYarnScheduler: Release request cache is cleaned up
2019-02-21 15:24:16,271 INFO org.apache.hadoop.yarn.server.resourcemanager.ClientRMService: Allocated new applicationId: 1
2019-02-21 15:24:18,896 INFO org.apache.hadoop.yarn.server.resourcemanager.scheduler.capacity.CapacityScheduler: Application 'application_1550783650344_0001' is submitted without priority hence considering default queue/cluster priority: 0
2019-02-21 15:24:18,896 INFO org.apache.hadoop.yarn.server.resourcemanager.scheduler.capacity.CapacityScheduler: Priority '0' is acceptable in queue : default for application: application_1550783650344_0001 for the user: anushamuppalla
2019-02-21 15:24:18,954 INFO org.apache.hadoop.yarn.server.resourcemanager.ClientRMService: Application with id 1 submitted by user anushamuppalla
2019-02-21 15:24:18,955 INFO org.apache.hadoop.yarn.server.resourcemanager.rmapp.RMAppImpl: Storing application with id application_1550783650344_0001
2019-02-21 15:24:18,960 INFO org.apache.hadoop.yarn.server.resourcemanager.RMAuditLogger: USER=anushamuppalla	IP=127.0.0.1	OPERATION=Submit Application Request	TARGET=ClientRMService	RESULT=SUCCESS	APPID=application_1550783650344_0001
2019-02-21 15:24:18,982 INFO org.apache.hadoop.yarn.server.resourcemanager.rmapp.RMAppImpl: application_1550783650344_0001 State change from NEW to NEW_SAVING on event=START
2019-02-21 15:24:18,983 INFO org.apache.hadoop.yarn.server.resourcemanager.recovery.RMStateStore: Storing info for app: application_1550783650344_0001
2019-02-21 15:24:18,985 INFO org.apache.hadoop.yarn.server.resourcemanager.rmapp.RMAppImpl: application_1550783650344_0001 State change from NEW_SAVING to SUBMITTED on event=APP_NEW_SAVED
2019-02-21 15:24:18,991 INFO org.apache.hadoop.yarn.server.resourcemanager.scheduler.capacity.ParentQueue: Application added - appId: application_1550783650344_0001 user: anushamuppalla leaf-queue of parent: root #applications: 1
2019-02-21 15:24:18,995 INFO org.apache.hadoop.yarn.server.resourcemanager.scheduler.capacity.CapacityScheduler: Accepted application application_1550783650344_0001 from user: anushamuppalla, in queue: default
2019-02-21 15:24:19,045 INFO org.apache.hadoop.yarn.server.resourcemanager.rmapp.RMAppImpl: application_1550783650344_0001 State change from SUBMITTED to ACCEPTED on event=APP_ACCEPTED
2019-02-21 15:24:19,133 INFO org.apache.hadoop.yarn.server.resourcemanager.ApplicationMasterService: Registering app attempt : appattempt_1550783650344_0001_000001
2019-02-21 15:24:19,135 INFO org.apache.hadoop.yarn.server.resourcemanager.rmapp.attempt.RMAppAttemptImpl: appattempt_1550783650344_0001_000001 State change from NEW to SUBMITTED
2019-02-21 15:24:19,206 WARN org.apache.hadoop.yarn.server.resourcemanager.scheduler.capacity.LeafQueue: maximum-am-resource-percent is insufficient to start a single application in queue, it is likely set too low. skipping enforcement to allow at least one application to start
2019-02-21 15:24:19,207 WARN org.apache.hadoop.yarn.server.resourcemanager.scheduler.capacity.LeafQueue: maximum-am-resource-percent is insufficient to start a single application in queue for user, it is likely set too low. skipping enforcement to allow at least one application to start
2019-02-21 15:24:19,214 INFO org.apache.hadoop.yarn.server.resourcemanager.scheduler.capacity.LeafQueue: Application application_1550783650344_0001 from user: anushamuppalla activated in queue: default
2019-02-21 15:24:19,215 INFO org.apache.hadoop.yarn.server.resourcemanager.scheduler.capacity.LeafQueue: Application added - appId: application_1550783650344_0001 user: anushamuppalla, leaf-queue: default #user-pending-applications: 0 #user-active-applications: 1 #queue-pending-applications: 0 #queue-active-applications: 1
2019-02-21 15:24:19,215 INFO org.apache.hadoop.yarn.server.resourcemanager.scheduler.capacity.CapacityScheduler: Added Application Attempt appattempt_1550783650344_0001_000001 to scheduler from user anushamuppalla in queue default
2019-02-21 15:24:19,221 INFO org.apache.hadoop.yarn.server.resourcemanager.rmapp.attempt.RMAppAttemptImpl: appattempt_1550783650344_0001_000001 State change from SUBMITTED to SCHEDULED
2019-02-21 15:24:19,452 INFO org.apache.hadoop.yarn.server.resourcemanager.rmcontainer.RMContainerImpl: container_1550783650344_0001_01_000001 Container Transitioned from NEW to ALLOCATED
2019-02-21 15:24:19,452 INFO org.apache.hadoop.yarn.server.resourcemanager.RMAuditLogger: USER=anushamuppalla	OPERATION=AM Allocated Container	TARGET=SchedulerApp	RESULT=SUCCESS	APPID=application_1550783650344_0001	CONTAINERID=container_1550783650344_0001_01_000001
2019-02-21 15:24:19,455 INFO org.apache.hadoop.yarn.server.resourcemanager.scheduler.SchedulerNode: Assigned container container_1550783650344_0001_01_000001 of capacity <memory:2048, vCores:1> on host anushas-air.kc.umkc.edu:56045, which has 1 containers, <memory:2048, vCores:1> used and <memory:6144, vCores:7> available after allocation
2019-02-21 15:24:19,456 INFO org.apache.hadoop.yarn.server.resourcemanager.scheduler.capacity.allocator.AbstractContainerAllocator: assignedContainer application attempt=appattempt_1550783650344_0001_000001 container=container_1550783650344_0001_01_000001 queue=org.apache.hadoop.yarn.server.resourcemanager.scheduler.capacity.allocator.RegularContainerAllocator@27e853a3 clusterResource=<memory:8192, vCores:8> type=OFF_SWITCH
2019-02-21 15:24:19,566 INFO org.apache.hadoop.yarn.server.resourcemanager.security.NMTokenSecretManagerInRM: Sending NMToken for nodeId : anushas-air.kc.umkc.edu:56045 for container : container_1550783650344_0001_01_000001
2019-02-21 15:24:19,601 INFO org.apache.hadoop.yarn.server.resourcemanager.rmcontainer.RMContainerImpl: container_1550783650344_0001_01_000001 Container Transitioned from ALLOCATED to ACQUIRED
2019-02-21 15:24:19,603 INFO org.apache.hadoop.yarn.server.resourcemanager.security.NMTokenSecretManagerInRM: Clear node set for appattempt_1550783650344_0001_000001
2019-02-21 15:24:19,603 INFO org.apache.hadoop.yarn.server.resourcemanager.rmapp.attempt.RMAppAttemptImpl: Storing attempt: AppId: application_1550783650344_0001 AttemptId: appattempt_1550783650344_0001_000001 MasterContainer: Container: [ContainerId: container_1550783650344_0001_01_000001, Version: 0, NodeId: anushas-air.kc.umkc.edu:56045, NodeHttpAddress: anushas-air.kc.umkc.edu:8042, Resource: <memory:2048, vCores:1>, Priority: 0, Token: Token { kind: ContainerToken, service: 10.205.2.163:56045 }, ]
2019-02-21 15:24:19,606 INFO org.apache.hadoop.yarn.server.resourcemanager.scheduler.capacity.ParentQueue: Re-sorting assigned queue: root.default stats: default: capacity=1.0, absoluteCapacity=1.0, usedResources=<memory:2048, vCores:1>, usedCapacity=0.25, absoluteUsedCapacity=0.25, numApps=1, numContainers=1
2019-02-21 15:24:19,607 INFO org.apache.hadoop.yarn.server.resourcemanager.scheduler.capacity.ParentQueue: assignedContainer queue=root usedCapacity=0.25 absoluteUsedCapacity=0.25 used=<memory:2048, vCores:1> cluster=<memory:8192, vCores:8>
2019-02-21 15:24:19,634 INFO org.apache.hadoop.yarn.server.resourcemanager.rmapp.attempt.RMAppAttemptImpl: appattempt_1550783650344_0001_000001 State change from SCHEDULED to ALLOCATED_SAVING
2019-02-21 15:24:19,651 INFO org.apache.hadoop.yarn.server.resourcemanager.rmapp.attempt.RMAppAttemptImpl: appattempt_1550783650344_0001_000001 State change from ALLOCATED_SAVING to ALLOCATED
2019-02-21 15:24:19,662 INFO org.apache.hadoop.yarn.server.resourcemanager.amlauncher.AMLauncher: Launching masterappattempt_1550783650344_0001_000001
2019-02-21 15:24:19,806 INFO org.apache.hadoop.yarn.server.resourcemanager.amlauncher.AMLauncher: Setting up container Container: [ContainerId: container_1550783650344_0001_01_000001, Version: 0, NodeId: anushas-air.kc.umkc.edu:56045, NodeHttpAddress: anushas-air.kc.umkc.edu:8042, Resource: <memory:2048, vCores:1>, Priority: 0, Token: Token { kind: ContainerToken, service: 10.205.2.163:56045 }, ] for AM appattempt_1550783650344_0001_000001
2019-02-21 15:24:19,807 INFO org.apache.hadoop.yarn.server.resourcemanager.security.AMRMTokenSecretManager: Create AMRMToken for ApplicationAttempt: appattempt_1550783650344_0001_000001
2019-02-21 15:24:19,816 INFO org.apache.hadoop.yarn.server.resourcemanager.security.AMRMTokenSecretManager: Creating password for appattempt_1550783650344_0001_000001
2019-02-21 15:24:20,825 INFO org.apache.hadoop.yarn.server.resourcemanager.amlauncher.AMLauncher: Done launching container Container: [ContainerId: container_1550783650344_0001_01_000001, Version: 0, NodeId: anushas-air.kc.umkc.edu:56045, NodeHttpAddress: anushas-air.kc.umkc.edu:8042, Resource: <memory:2048, vCores:1>, Priority: 0, Token: Token { kind: ContainerToken, service: 10.205.2.163:56045 }, ] for AM appattempt_1550783650344_0001_000001
2019-02-21 15:24:20,826 INFO org.apache.hadoop.yarn.server.resourcemanager.rmapp.attempt.RMAppAttemptImpl: appattempt_1550783650344_0001_000001 State change from ALLOCATED to LAUNCHED
2019-02-21 15:24:21,416 INFO org.apache.hadoop.yarn.server.resourcemanager.rmcontainer.RMContainerImpl: container_1550783650344_0001_01_000001 Container Transitioned from ACQUIRED to RUNNING
2019-02-21 15:24:40,672 INFO SecurityLogger.org.apache.hadoop.ipc.Server: Auth successful for appattempt_1550783650344_0001_000001 (auth:SIMPLE)
2019-02-21 15:24:40,700 INFO org.apache.hadoop.yarn.server.resourcemanager.ApplicationMasterService: AM registration appattempt_1550783650344_0001_000001
2019-02-21 15:24:40,704 INFO org.apache.hadoop.yarn.server.resourcemanager.RMAuditLogger: USER=anushamuppalla	IP=127.0.0.1	OPERATION=Register App Master	TARGET=ApplicationMasterService	RESULT=SUCCESS	APPID=application_1550783650344_0001	APPATTEMPTID=appattempt_1550783650344_0001_000001
2019-02-21 15:24:40,704 INFO org.apache.hadoop.yarn.server.resourcemanager.rmapp.attempt.RMAppAttemptImpl: appattempt_1550783650344_0001_000001 State change from LAUNCHED to RUNNING
2019-02-21 15:24:40,705 INFO org.apache.hadoop.yarn.server.resourcemanager.rmapp.RMAppImpl: application_1550783650344_0001 State change from ACCEPTED to RUNNING on event=ATTEMPT_REGISTERED
2019-02-21 15:24:42,565 INFO org.apache.hadoop.yarn.server.resourcemanager.rmcontainer.RMContainerImpl: container_1550783650344_0001_01_000002 Container Transitioned from NEW to ALLOCATED
2019-02-21 15:24:42,565 INFO org.apache.hadoop.yarn.server.resourcemanager.RMAuditLogger: USER=anushamuppalla	OPERATION=AM Allocated Container	TARGET=SchedulerApp	RESULT=SUCCESS	APPID=application_1550783650344_0001	CONTAINERID=container_1550783650344_0001_01_000002
2019-02-21 15:24:42,566 INFO org.apache.hadoop.yarn.server.resourcemanager.scheduler.SchedulerNode: Assigned container container_1550783650344_0001_01_000002 of capacity <memory:1024, vCores:1> on host anushas-air.kc.umkc.edu:56045, which has 2 containers, <memory:3072, vCores:2> used and <memory:5120, vCores:6> available after allocation
2019-02-21 15:24:42,566 INFO org.apache.hadoop.yarn.server.resourcemanager.scheduler.capacity.allocator.AbstractContainerAllocator: assignedContainer application attempt=appattempt_1550783650344_0001_000001 container=container_1550783650344_0001_01_000002 queue=org.apache.hadoop.yarn.server.resourcemanager.scheduler.capacity.allocator.RegularContainerAllocator@27e853a3 clusterResource=<memory:8192, vCores:8> type=NODE_LOCAL
2019-02-21 15:24:42,567 INFO org.apache.hadoop.yarn.server.resourcemanager.scheduler.capacity.ParentQueue: Re-sorting assigned queue: root.default stats: default: capacity=1.0, absoluteCapacity=1.0, usedResources=<memory:3072, vCores:2>, usedCapacity=0.375, absoluteUsedCapacity=0.375, numApps=1, numContainers=2
2019-02-21 15:24:42,567 INFO org.apache.hadoop.yarn.server.resourcemanager.scheduler.capacity.ParentQueue: assignedContainer queue=root usedCapacity=0.375 absoluteUsedCapacity=0.375 used=<memory:3072, vCores:2> cluster=<memory:8192, vCores:8>
2019-02-21 15:24:42,903 INFO org.apache.hadoop.yarn.server.resourcemanager.security.NMTokenSecretManagerInRM: Sending NMToken for nodeId : anushas-air.kc.umkc.edu:56045 for container : container_1550783650344_0001_01_000002
2019-02-21 15:24:42,907 INFO org.apache.hadoop.yarn.server.resourcemanager.rmcontainer.RMContainerImpl: container_1550783650344_0001_01_000002 Container Transitioned from ALLOCATED to ACQUIRED
2019-02-21 15:24:43,966 INFO org.apache.hadoop.yarn.server.resourcemanager.rmcontainer.RMContainerImpl: container_1550783650344_0001_01_000002 Container Transitioned from ACQUIRED to RELEASED
2019-02-21 15:24:43,967 INFO org.apache.hadoop.yarn.server.resourcemanager.RMAuditLogger: USER=anushamuppalla	IP=127.0.0.1	OPERATION=AM Released Container	TARGET=SchedulerApp	RESULT=SUCCESS	APPID=application_1550783650344_0001	CONTAINERID=container_1550783650344_0001_01_000002
2019-02-21 15:24:43,969 INFO org.apache.hadoop.yarn.server.resourcemanager.scheduler.SchedulerNode: Released container container_1550783650344_0001_01_000002 of capacity <memory:1024, vCores:1> on host anushas-air.kc.umkc.edu:56045, which currently has 1 containers, <memory:2048, vCores:1> used and <memory:6144, vCores:7> available, release resources=true
2019-02-21 15:24:43,973 INFO org.apache.hadoop.yarn.server.resourcemanager.scheduler.AppSchedulingInfo: checking for deactivate of application :application_1550783650344_0001
2019-02-21 15:24:44,576 INFO org.apache.hadoop.yarn.server.resourcemanager.rmcontainer.RMContainerImpl: container_1550783650344_0001_01_000003 Container Transitioned from NEW to ALLOCATED
2019-02-21 15:24:44,576 INFO org.apache.hadoop.yarn.server.resourcemanager.RMAuditLogger: USER=anushamuppalla	OPERATION=AM Allocated Container	TARGET=SchedulerApp	RESULT=SUCCESS	APPID=application_1550783650344_0001	CONTAINERID=container_1550783650344_0001_01_000003
2019-02-21 15:24:44,577 INFO org.apache.hadoop.yarn.server.resourcemanager.scheduler.SchedulerNode: Assigned container container_1550783650344_0001_01_000003 of capacity <memory:1024, vCores:1> on host anushas-air.kc.umkc.edu:56045, which has 2 containers, <memory:3072, vCores:2> used and <memory:5120, vCores:6> available after allocation
2019-02-21 15:24:44,577 INFO org.apache.hadoop.yarn.server.resourcemanager.scheduler.capacity.allocator.AbstractContainerAllocator: assignedContainer application attempt=appattempt_1550783650344_0001_000001 container=container_1550783650344_0001_01_000003 queue=org.apache.hadoop.yarn.server.resourcemanager.scheduler.capacity.allocator.RegularContainerAllocator@27e853a3 clusterResource=<memory:8192, vCores:8> type=OFF_SWITCH
2019-02-21 15:24:44,577 INFO org.apache.hadoop.yarn.server.resourcemanager.scheduler.capacity.ParentQueue: Re-sorting assigned queue: root.default stats: default: capacity=1.0, absoluteCapacity=1.0, usedResources=<memory:3072, vCores:2>, usedCapacity=0.375, absoluteUsedCapacity=0.375, numApps=1, numContainers=2
2019-02-21 15:24:44,578 INFO org.apache.hadoop.yarn.server.resourcemanager.scheduler.capacity.ParentQueue: assignedContainer queue=root usedCapacity=0.375 absoluteUsedCapacity=0.375 used=<memory:3072, vCores:2> cluster=<memory:8192, vCores:8>
2019-02-21 15:24:44,998 INFO org.apache.hadoop.yarn.server.resourcemanager.rmcontainer.RMContainerImpl: container_1550783650344_0001_01_000003 Container Transitioned from ALLOCATED to ACQUIRED
2019-02-21 15:24:46,014 INFO org.apache.hadoop.yarn.server.resourcemanager.rmcontainer.RMContainerImpl: container_1550783650344_0001_01_000003 Container Transitioned from ACQUIRED to RELEASED
2019-02-21 15:24:46,015 INFO org.apache.hadoop.yarn.server.resourcemanager.RMAuditLogger: USER=anushamuppalla	IP=127.0.0.1	OPERATION=AM Released Container	TARGET=SchedulerApp	RESULT=SUCCESS	APPID=application_1550783650344_0001	CONTAINERID=container_1550783650344_0001_01_000003
2019-02-21 15:24:46,015 INFO org.apache.hadoop.yarn.server.resourcemanager.scheduler.SchedulerNode: Released container container_1550783650344_0001_01_000003 of capacity <memory:1024, vCores:1> on host anushas-air.kc.umkc.edu:56045, which currently has 1 containers, <memory:2048, vCores:1> used and <memory:6144, vCores:7> available, release resources=true
2019-02-21 15:24:46,591 INFO org.apache.hadoop.yarn.server.resourcemanager.rmcontainer.RMContainerImpl: container_1550783650344_0001_01_000004 Container Transitioned from NEW to ALLOCATED
2019-02-21 15:24:46,592 INFO org.apache.hadoop.yarn.server.resourcemanager.RMAuditLogger: USER=anushamuppalla	OPERATION=AM Allocated Container	TARGET=SchedulerApp	RESULT=SUCCESS	APPID=application_1550783650344_0001	CONTAINERID=container_1550783650344_0001_01_000004
2019-02-21 15:24:46,592 INFO org.apache.hadoop.yarn.server.resourcemanager.scheduler.SchedulerNode: Assigned container container_1550783650344_0001_01_000004 of capacity <memory:1024, vCores:1> on host anushas-air.kc.umkc.edu:56045, which has 2 containers, <memory:3072, vCores:2> used and <memory:5120, vCores:6> available after allocation
2019-02-21 15:24:46,592 INFO org.apache.hadoop.yarn.server.resourcemanager.scheduler.capacity.allocator.AbstractContainerAllocator: assignedContainer application attempt=appattempt_1550783650344_0001_000001 container=container_1550783650344_0001_01_000004 queue=org.apache.hadoop.yarn.server.resourcemanager.scheduler.capacity.allocator.RegularContainerAllocator@27e853a3 clusterResource=<memory:8192, vCores:8> type=OFF_SWITCH
2019-02-21 15:24:46,593 INFO org.apache.hadoop.yarn.server.resourcemanager.scheduler.capacity.ParentQueue: Re-sorting assigned queue: root.default stats: default: capacity=1.0, absoluteCapacity=1.0, usedResources=<memory:3072, vCores:2>, usedCapacity=0.375, absoluteUsedCapacity=0.375, numApps=1, numContainers=2
2019-02-21 15:24:46,593 INFO org.apache.hadoop.yarn.server.resourcemanager.scheduler.capacity.ParentQueue: assignedContainer queue=root usedCapacity=0.375 absoluteUsedCapacity=0.375 used=<memory:3072, vCores:2> cluster=<memory:8192, vCores:8>
2019-02-21 15:24:47,030 INFO org.apache.hadoop.yarn.server.resourcemanager.rmcontainer.RMContainerImpl: container_1550783650344_0001_01_000004 Container Transitioned from ALLOCATED to ACQUIRED
2019-02-21 15:24:48,044 INFO org.apache.hadoop.yarn.server.resourcemanager.rmcontainer.RMContainerImpl: container_1550783650344_0001_01_000004 Container Transitioned from ACQUIRED to RELEASED
2019-02-21 15:24:48,045 INFO org.apache.hadoop.yarn.server.resourcemanager.RMAuditLogger: USER=anushamuppalla	IP=127.0.0.1	OPERATION=AM Released Container	TARGET=SchedulerApp	RESULT=SUCCESS	APPID=application_1550783650344_0001	CONTAINERID=container_1550783650344_0001_01_000004
2019-02-21 15:24:48,045 INFO org.apache.hadoop.yarn.server.resourcemanager.scheduler.SchedulerNode: Released container container_1550783650344_0001_01_000004 of capacity <memory:1024, vCores:1> on host anushas-air.kc.umkc.edu:56045, which currently has 1 containers, <memory:2048, vCores:1> used and <memory:6144, vCores:7> available, release resources=true
2019-02-21 15:24:48,047 INFO org.apache.hadoop.yarn.server.resourcemanager.ApplicationMasterService: blacklist are updated in Scheduler.blacklistAdditions: [anushas-air.kc.umkc.edu], blacklistRemovals: []
2019-02-21 15:24:49,058 INFO org.apache.hadoop.yarn.server.resourcemanager.ApplicationMasterService: blacklist are updated in Scheduler.blacklistAdditions: [], blacklistRemovals: [anushas-air.kc.umkc.edu]
2019-02-21 15:24:49,608 INFO org.apache.hadoop.yarn.server.resourcemanager.rmcontainer.RMContainerImpl: container_1550783650344_0001_01_000005 Container Transitioned from NEW to ALLOCATED
2019-02-21 15:24:49,609 INFO org.apache.hadoop.yarn.server.resourcemanager.RMAuditLogger: USER=anushamuppalla	OPERATION=AM Allocated Container	TARGET=SchedulerApp	RESULT=SUCCESS	APPID=application_1550783650344_0001	CONTAINERID=container_1550783650344_0001_01_000005
2019-02-21 15:24:49,609 INFO org.apache.hadoop.yarn.server.resourcemanager.scheduler.SchedulerNode: Assigned container container_1550783650344_0001_01_000005 of capacity <memory:1024, vCores:1> on host anushas-air.kc.umkc.edu:56045, which has 2 containers, <memory:3072, vCores:2> used and <memory:5120, vCores:6> available after allocation
2019-02-21 15:24:49,609 INFO org.apache.hadoop.yarn.server.resourcemanager.scheduler.capacity.allocator.AbstractContainerAllocator: assignedContainer application attempt=appattempt_1550783650344_0001_000001 container=container_1550783650344_0001_01_000005 queue=org.apache.hadoop.yarn.server.resourcemanager.scheduler.capacity.allocator.RegularContainerAllocator@27e853a3 clusterResource=<memory:8192, vCores:8> type=OFF_SWITCH
2019-02-21 15:24:49,610 INFO org.apache.hadoop.yarn.server.resourcemanager.scheduler.capacity.ParentQueue: Re-sorting assigned queue: root.default stats: default: capacity=1.0, absoluteCapacity=1.0, usedResources=<memory:3072, vCores:2>, usedCapacity=0.375, absoluteUsedCapacity=0.375, numApps=1, numContainers=2
2019-02-21 15:24:49,610 INFO org.apache.hadoop.yarn.server.resourcemanager.scheduler.capacity.ParentQueue: assignedContainer queue=root usedCapacity=0.375 absoluteUsedCapacity=0.375 used=<memory:3072, vCores:2> cluster=<memory:8192, vCores:8>
2019-02-21 15:24:50,079 INFO org.apache.hadoop.yarn.server.resourcemanager.rmcontainer.RMContainerImpl: container_1550783650344_0001_01_000005 Container Transitioned from ALLOCATED to ACQUIRED
2019-02-21 15:24:51,099 INFO org.apache.hadoop.yarn.server.resourcemanager.rmcontainer.RMContainerImpl: container_1550783650344_0001_01_000005 Container Transitioned from ACQUIRED to RELEASED
2019-02-21 15:24:51,101 INFO org.apache.hadoop.yarn.server.resourcemanager.RMAuditLogger: USER=anushamuppalla	IP=127.0.0.1	OPERATION=AM Released Container	TARGET=SchedulerApp	RESULT=SUCCESS	APPID=application_1550783650344_0001	CONTAINERID=container_1550783650344_0001_01_000005
2019-02-21 15:24:51,101 INFO org.apache.hadoop.yarn.server.resourcemanager.scheduler.SchedulerNode: Released container container_1550783650344_0001_01_000005 of capacity <memory:1024, vCores:1> on host anushas-air.kc.umkc.edu:56045, which currently has 1 containers, <memory:2048, vCores:1> used and <memory:6144, vCores:7> available, release resources=true
2019-02-21 15:24:51,103 INFO org.apache.hadoop.yarn.server.resourcemanager.scheduler.AppSchedulingInfo: checking for deactivate of application :application_1550783650344_0001
2019-02-21 15:24:51,606 INFO org.apache.hadoop.yarn.server.resourcemanager.rmapp.attempt.RMAppAttemptImpl: Updating application attempt appattempt_1550783650344_0001_000001 with final state: FINISHING, and exit status: -1000
2019-02-21 15:24:51,611 INFO org.apache.hadoop.yarn.server.resourcemanager.rmapp.attempt.RMAppAttemptImpl: appattempt_1550783650344_0001_000001 State change from RUNNING to FINAL_SAVING
2019-02-21 15:24:51,611 INFO org.apache.hadoop.yarn.server.resourcemanager.rmapp.RMAppImpl: Updating application application_1550783650344_0001 with final state: FINISHING
2019-02-21 15:24:51,612 INFO org.apache.hadoop.yarn.server.resourcemanager.rmapp.RMAppImpl: application_1550783650344_0001 State change from RUNNING to FINAL_SAVING on event=ATTEMPT_UNREGISTERED
2019-02-21 15:24:51,616 INFO org.apache.hadoop.yarn.server.resourcemanager.recovery.RMStateStore: Updating info for app: application_1550783650344_0001
2019-02-21 15:24:51,619 INFO org.apache.hadoop.yarn.server.resourcemanager.rmapp.attempt.RMAppAttemptImpl: appattempt_1550783650344_0001_000001 State change from FINAL_SAVING to FINISHING
2019-02-21 15:24:51,620 INFO org.apache.hadoop.yarn.server.resourcemanager.rmapp.RMAppImpl: application_1550783650344_0001 State change from FINAL_SAVING to FINISHING on event=APP_UPDATE_SAVED
2019-02-21 15:24:52,657 INFO org.apache.hadoop.yarn.server.resourcemanager.ApplicationMasterService: application_1550783650344_0001 unregistered successfully. 
2019-02-21 15:24:58,082 INFO org.apache.hadoop.yarn.server.resourcemanager.rmcontainer.RMContainerImpl: container_1550783650344_0001_01_000001 Container Transitioned from RUNNING to COMPLETED
2019-02-21 15:24:58,082 INFO org.apache.hadoop.yarn.server.resourcemanager.ApplicationMasterService: Unregistering app attempt : appattempt_1550783650344_0001_000001
2019-02-21 15:24:58,083 INFO org.apache.hadoop.yarn.server.resourcemanager.RMAuditLogger: USER=anushamuppalla	OPERATION=AM Released Container	TARGET=SchedulerApp	RESULT=SUCCESS	APPID=application_1550783650344_0001	CONTAINERID=container_1550783650344_0001_01_000001
2019-02-21 15:24:58,084 INFO org.apache.hadoop.yarn.server.resourcemanager.scheduler.SchedulerNode: Released container container_1550783650344_0001_01_000001 of capacity <memory:2048, vCores:1> on host anushas-air.kc.umkc.edu:56045, which currently has 0 containers, <memory:0, vCores:0> used and <memory:8192, vCores:8> available, release resources=true
2019-02-21 15:24:58,085 INFO org.apache.hadoop.yarn.server.resourcemanager.security.AMRMTokenSecretManager: Application finished, removing password for appattempt_1550783650344_0001_000001
2019-02-21 15:24:58,085 INFO org.apache.hadoop.yarn.server.resourcemanager.rmapp.attempt.RMAppAttemptImpl: appattempt_1550783650344_0001_000001 State change from FINISHING to FINISHED
2019-02-21 15:24:58,091 INFO org.apache.hadoop.yarn.server.resourcemanager.rmapp.RMAppImpl: application_1550783650344_0001 State change from FINISHING to FINISHED on event=ATTEMPT_FINISHED
2019-02-21 15:24:58,092 INFO org.apache.hadoop.yarn.server.resourcemanager.scheduler.capacity.CapacityScheduler: Application Attempt appattempt_1550783650344_0001_000001 is done. finalState=FINISHED
2019-02-21 15:24:58,095 INFO org.apache.hadoop.yarn.server.resourcemanager.scheduler.AppSchedulingInfo: Application application_1550783650344_0001 requests cleared
2019-02-21 15:24:58,096 INFO org.apache.hadoop.yarn.server.resourcemanager.RMAuditLogger: USER=anushamuppalla	OPERATION=Application Finished - Succeeded	TARGET=RMAppManager	RESULT=SUCCESS	APPID=application_1550783650344_0001
2019-02-21 15:24:58,096 INFO org.apache.hadoop.yarn.server.resourcemanager.scheduler.capacity.LeafQueue: Application removed - appId: application_1550783650344_0001 user: anushamuppalla queue: default #user-pending-applications: 0 #user-active-applications: 0 #queue-pending-applications: 0 #queue-active-applications: 0
2019-02-21 15:24:58,097 INFO org.apache.hadoop.yarn.server.resourcemanager.scheduler.capacity.ParentQueue: Application removed - appId: application_1550783650344_0001 user: anushamuppalla leaf-queue of parent: root #applications: 0
2019-02-21 15:24:58,099 INFO org.apache.hadoop.yarn.server.resourcemanager.amlauncher.AMLauncher: Cleaning master appattempt_1550783650344_0001_000001
2019-02-21 15:24:58,103 INFO org.apache.hadoop.yarn.server.resourcemanager.RMAppManager$ApplicationSummary: appId=application_1550783650344_0001,name=word count,user=anushamuppalla,queue=default,state=FINISHED,trackingUrl=http://anushas-air.kc.umkc.edu:8088/proxy/application_1550783650344_0001/,appMasterHost=anushas-air.kc.umkc.edu,startTime=1550784258938,finishTime=1550784291611,finalStatus=FAILED,memorySeconds=85045,vcoreSeconds=42,preemptedMemorySeconds=0,preemptedVcoreSeconds=0,preemptedAMContainers=0,preemptedNonAMContainers=0,preemptedResources=<memory:0\, vCores:0>,applicationType=MAPREDUCE
2019-02-21 15:33:28,537 INFO org.apache.hadoop.yarn.server.resourcemanager.ClientRMService: Allocated new applicationId: 2
2019-02-21 15:33:31,042 INFO org.apache.hadoop.yarn.server.resourcemanager.scheduler.capacity.CapacityScheduler: Application 'application_1550783650344_0002' is submitted without priority hence considering default queue/cluster priority: 0
2019-02-21 15:33:31,043 INFO org.apache.hadoop.yarn.server.resourcemanager.scheduler.capacity.CapacityScheduler: Priority '0' is acceptable in queue : default for application: application_1550783650344_0002 for the user: anushamuppalla
2019-02-21 15:33:31,044 INFO org.apache.hadoop.yarn.server.resourcemanager.ClientRMService: Application with id 2 submitted by user anushamuppalla
2019-02-21 15:33:31,044 INFO org.apache.hadoop.yarn.server.resourcemanager.rmapp.RMAppImpl: Storing application with id application_1550783650344_0002
2019-02-21 15:33:31,045 INFO org.apache.hadoop.yarn.server.resourcemanager.RMAuditLogger: USER=anushamuppalla	IP=127.0.0.1	OPERATION=Submit Application Request	TARGET=ClientRMService	RESULT=SUCCESS	APPID=application_1550783650344_0002
2019-02-21 15:33:31,045 INFO org.apache.hadoop.yarn.server.resourcemanager.rmapp.RMAppImpl: application_1550783650344_0002 State change from NEW to NEW_SAVING on event=START
2019-02-21 15:33:31,045 INFO org.apache.hadoop.yarn.server.resourcemanager.recovery.RMStateStore: Storing info for app: application_1550783650344_0002
2019-02-21 15:33:31,046 INFO org.apache.hadoop.yarn.server.resourcemanager.rmapp.RMAppImpl: application_1550783650344_0002 State change from NEW_SAVING to SUBMITTED on event=APP_NEW_SAVED
2019-02-21 15:33:31,047 INFO org.apache.hadoop.yarn.server.resourcemanager.scheduler.capacity.ParentQueue: Application added - appId: application_1550783650344_0002 user: anushamuppalla leaf-queue of parent: root #applications: 1
2019-02-21 15:33:31,047 INFO org.apache.hadoop.yarn.server.resourcemanager.scheduler.capacity.CapacityScheduler: Accepted application application_1550783650344_0002 from user: anushamuppalla, in queue: default
2019-02-21 15:33:31,069 INFO org.apache.hadoop.yarn.server.resourcemanager.rmapp.RMAppImpl: application_1550783650344_0002 State change from SUBMITTED to ACCEPTED on event=APP_ACCEPTED
2019-02-21 15:33:31,070 INFO org.apache.hadoop.yarn.server.resourcemanager.ApplicationMasterService: Registering app attempt : appattempt_1550783650344_0002_000001
2019-02-21 15:33:31,070 INFO org.apache.hadoop.yarn.server.resourcemanager.rmapp.attempt.RMAppAttemptImpl: appattempt_1550783650344_0002_000001 State change from NEW to SUBMITTED
2019-02-21 15:33:31,072 WARN org.apache.hadoop.yarn.server.resourcemanager.scheduler.capacity.LeafQueue: maximum-am-resource-percent is insufficient to start a single application in queue, it is likely set too low. skipping enforcement to allow at least one application to start
2019-02-21 15:33:31,072 WARN org.apache.hadoop.yarn.server.resourcemanager.scheduler.capacity.LeafQueue: maximum-am-resource-percent is insufficient to start a single application in queue for user, it is likely set too low. skipping enforcement to allow at least one application to start
2019-02-21 15:33:31,073 INFO org.apache.hadoop.yarn.server.resourcemanager.scheduler.capacity.LeafQueue: Application application_1550783650344_0002 from user: anushamuppalla activated in queue: default
2019-02-21 15:33:31,074 INFO org.apache.hadoop.yarn.server.resourcemanager.scheduler.capacity.LeafQueue: Application added - appId: application_1550783650344_0002 user: anushamuppalla, leaf-queue: default #user-pending-applications: 0 #user-active-applications: 1 #queue-pending-applications: 0 #queue-active-applications: 1
2019-02-21 15:33:31,074 INFO org.apache.hadoop.yarn.server.resourcemanager.scheduler.capacity.CapacityScheduler: Added Application Attempt appattempt_1550783650344_0002_000001 to scheduler from user anushamuppalla in queue default
2019-02-21 15:33:31,077 INFO org.apache.hadoop.yarn.server.resourcemanager.rmapp.attempt.RMAppAttemptImpl: appattempt_1550783650344_0002_000001 State change from SUBMITTED to SCHEDULED
2019-02-21 15:33:31,804 INFO org.apache.hadoop.yarn.server.resourcemanager.rmcontainer.RMContainerImpl: container_1550783650344_0002_01_000001 Container Transitioned from NEW to ALLOCATED
2019-02-21 15:33:31,805 INFO org.apache.hadoop.yarn.server.resourcemanager.RMAuditLogger: USER=anushamuppalla	OPERATION=AM Allocated Container	TARGET=SchedulerApp	RESULT=SUCCESS	APPID=application_1550783650344_0002	CONTAINERID=container_1550783650344_0002_01_000001
2019-02-21 15:33:31,805 INFO org.apache.hadoop.yarn.server.resourcemanager.scheduler.SchedulerNode: Assigned container container_1550783650344_0002_01_000001 of capacity <memory:2048, vCores:1> on host anushas-air.kc.umkc.edu:56045, which has 1 containers, <memory:2048, vCores:1> used and <memory:6144, vCores:7> available after allocation
2019-02-21 15:33:31,805 INFO org.apache.hadoop.yarn.server.resourcemanager.scheduler.capacity.allocator.AbstractContainerAllocator: assignedContainer application attempt=appattempt_1550783650344_0002_000001 container=container_1550783650344_0002_01_000001 queue=org.apache.hadoop.yarn.server.resourcemanager.scheduler.capacity.allocator.RegularContainerAllocator@4450a442 clusterResource=<memory:8192, vCores:8> type=OFF_SWITCH
2019-02-21 15:33:31,808 INFO org.apache.hadoop.yarn.server.resourcemanager.security.NMTokenSecretManagerInRM: Sending NMToken for nodeId : anushas-air.kc.umkc.edu:56045 for container : container_1550783650344_0002_01_000001
2019-02-21 15:33:31,810 INFO org.apache.hadoop.yarn.server.resourcemanager.rmcontainer.RMContainerImpl: container_1550783650344_0002_01_000001 Container Transitioned from ALLOCATED to ACQUIRED
2019-02-21 15:33:31,811 INFO org.apache.hadoop.yarn.server.resourcemanager.security.NMTokenSecretManagerInRM: Clear node set for appattempt_1550783650344_0002_000001
2019-02-21 15:33:31,811 INFO org.apache.hadoop.yarn.server.resourcemanager.rmapp.attempt.RMAppAttemptImpl: Storing attempt: AppId: application_1550783650344_0002 AttemptId: appattempt_1550783650344_0002_000001 MasterContainer: Container: [ContainerId: container_1550783650344_0002_01_000001, Version: 0, NodeId: anushas-air.kc.umkc.edu:56045, NodeHttpAddress: anushas-air.kc.umkc.edu:8042, Resource: <memory:2048, vCores:1>, Priority: 0, Token: Token { kind: ContainerToken, service: 10.205.2.163:56045 }, ]
2019-02-21 15:33:31,811 INFO org.apache.hadoop.yarn.server.resourcemanager.scheduler.capacity.ParentQueue: Re-sorting assigned queue: root.default stats: default: capacity=1.0, absoluteCapacity=1.0, usedResources=<memory:2048, vCores:1>, usedCapacity=0.25, absoluteUsedCapacity=0.25, numApps=1, numContainers=1
2019-02-21 15:33:31,811 INFO org.apache.hadoop.yarn.server.resourcemanager.rmapp.attempt.RMAppAttemptImpl: appattempt_1550783650344_0002_000001 State change from SCHEDULED to ALLOCATED_SAVING
2019-02-21 15:33:31,812 INFO org.apache.hadoop.yarn.server.resourcemanager.scheduler.capacity.ParentQueue: assignedContainer queue=root usedCapacity=0.25 absoluteUsedCapacity=0.25 used=<memory:2048, vCores:1> cluster=<memory:8192, vCores:8>
2019-02-21 15:33:31,812 INFO org.apache.hadoop.yarn.server.resourcemanager.rmapp.attempt.RMAppAttemptImpl: appattempt_1550783650344_0002_000001 State change from ALLOCATED_SAVING to ALLOCATED
2019-02-21 15:33:31,814 INFO org.apache.hadoop.yarn.server.resourcemanager.amlauncher.AMLauncher: Launching masterappattempt_1550783650344_0002_000001
2019-02-21 15:33:31,819 INFO org.apache.hadoop.yarn.server.resourcemanager.amlauncher.AMLauncher: Setting up container Container: [ContainerId: container_1550783650344_0002_01_000001, Version: 0, NodeId: anushas-air.kc.umkc.edu:56045, NodeHttpAddress: anushas-air.kc.umkc.edu:8042, Resource: <memory:2048, vCores:1>, Priority: 0, Token: Token { kind: ContainerToken, service: 10.205.2.163:56045 }, ] for AM appattempt_1550783650344_0002_000001
2019-02-21 15:33:31,820 INFO org.apache.hadoop.yarn.server.resourcemanager.security.AMRMTokenSecretManager: Create AMRMToken for ApplicationAttempt: appattempt_1550783650344_0002_000001
2019-02-21 15:33:31,820 INFO org.apache.hadoop.yarn.server.resourcemanager.security.AMRMTokenSecretManager: Creating password for appattempt_1550783650344_0002_000001
2019-02-21 15:33:31,852 INFO org.apache.hadoop.yarn.server.resourcemanager.amlauncher.AMLauncher: Done launching container Container: [ContainerId: container_1550783650344_0002_01_000001, Version: 0, NodeId: anushas-air.kc.umkc.edu:56045, NodeHttpAddress: anushas-air.kc.umkc.edu:8042, Resource: <memory:2048, vCores:1>, Priority: 0, Token: Token { kind: ContainerToken, service: 10.205.2.163:56045 }, ] for AM appattempt_1550783650344_0002_000001
2019-02-21 15:33:31,852 INFO org.apache.hadoop.yarn.server.resourcemanager.rmapp.attempt.RMAppAttemptImpl: appattempt_1550783650344_0002_000001 State change from ALLOCATED to LAUNCHED
2019-02-21 15:33:32,807 INFO org.apache.hadoop.yarn.server.resourcemanager.rmcontainer.RMContainerImpl: container_1550783650344_0002_01_000001 Container Transitioned from ACQUIRED to RUNNING
2019-02-21 15:33:49,086 INFO SecurityLogger.org.apache.hadoop.ipc.Server: Auth successful for appattempt_1550783650344_0002_000001 (auth:SIMPLE)
2019-02-21 15:33:49,100 INFO org.apache.hadoop.yarn.server.resourcemanager.ApplicationMasterService: AM registration appattempt_1550783650344_0002_000001
2019-02-21 15:33:49,100 INFO org.apache.hadoop.yarn.server.resourcemanager.RMAuditLogger: USER=anushamuppalla	IP=127.0.0.1	OPERATION=Register App Master	TARGET=ApplicationMasterService	RESULT=SUCCESS	APPID=application_1550783650344_0002	APPATTEMPTID=appattempt_1550783650344_0002_000001
2019-02-21 15:33:49,100 INFO org.apache.hadoop.yarn.server.resourcemanager.rmapp.attempt.RMAppAttemptImpl: appattempt_1550783650344_0002_000001 State change from LAUNCHED to RUNNING
2019-02-21 15:33:49,101 INFO org.apache.hadoop.yarn.server.resourcemanager.rmapp.RMAppImpl: application_1550783650344_0002 State change from ACCEPTED to RUNNING on event=ATTEMPT_REGISTERED
2019-02-21 15:33:50,914 INFO org.apache.hadoop.yarn.server.resourcemanager.rmcontainer.RMContainerImpl: container_1550783650344_0002_01_000002 Container Transitioned from NEW to ALLOCATED
2019-02-21 15:33:50,917 INFO org.apache.hadoop.yarn.server.resourcemanager.RMAuditLogger: USER=anushamuppalla	OPERATION=AM Allocated Container	TARGET=SchedulerApp	RESULT=SUCCESS	APPID=application_1550783650344_0002	CONTAINERID=container_1550783650344_0002_01_000002
2019-02-21 15:33:50,917 INFO org.apache.hadoop.yarn.server.resourcemanager.scheduler.SchedulerNode: Assigned container container_1550783650344_0002_01_000002 of capacity <memory:1024, vCores:1> on host anushas-air.kc.umkc.edu:56045, which has 2 containers, <memory:3072, vCores:2> used and <memory:5120, vCores:6> available after allocation
2019-02-21 15:33:50,918 INFO org.apache.hadoop.yarn.server.resourcemanager.scheduler.capacity.allocator.AbstractContainerAllocator: assignedContainer application attempt=appattempt_1550783650344_0002_000001 container=container_1550783650344_0002_01_000002 queue=org.apache.hadoop.yarn.server.resourcemanager.scheduler.capacity.allocator.RegularContainerAllocator@4450a442 clusterResource=<memory:8192, vCores:8> type=NODE_LOCAL
2019-02-21 15:33:50,919 INFO org.apache.hadoop.yarn.server.resourcemanager.scheduler.capacity.ParentQueue: Re-sorting assigned queue: root.default stats: default: capacity=1.0, absoluteCapacity=1.0, usedResources=<memory:3072, vCores:2>, usedCapacity=0.375, absoluteUsedCapacity=0.375, numApps=1, numContainers=2
2019-02-21 15:33:50,919 INFO org.apache.hadoop.yarn.server.resourcemanager.scheduler.capacity.ParentQueue: assignedContainer queue=root usedCapacity=0.375 absoluteUsedCapacity=0.375 used=<memory:3072, vCores:2> cluster=<memory:8192, vCores:8>
2019-02-21 15:33:51,257 INFO org.apache.hadoop.yarn.server.resourcemanager.security.NMTokenSecretManagerInRM: Sending NMToken for nodeId : anushas-air.kc.umkc.edu:56045 for container : container_1550783650344_0002_01_000002
2019-02-21 15:33:51,259 INFO org.apache.hadoop.yarn.server.resourcemanager.rmcontainer.RMContainerImpl: container_1550783650344_0002_01_000002 Container Transitioned from ALLOCATED to ACQUIRED
2019-02-21 15:33:52,296 INFO org.apache.hadoop.yarn.server.resourcemanager.rmcontainer.RMContainerImpl: container_1550783650344_0002_01_000002 Container Transitioned from ACQUIRED to RELEASED
2019-02-21 15:33:52,297 INFO org.apache.hadoop.yarn.server.resourcemanager.RMAuditLogger: USER=anushamuppalla	IP=127.0.0.1	OPERATION=AM Released Container	TARGET=SchedulerApp	RESULT=SUCCESS	APPID=application_1550783650344_0002	CONTAINERID=container_1550783650344_0002_01_000002
2019-02-21 15:33:52,297 INFO org.apache.hadoop.yarn.server.resourcemanager.scheduler.SchedulerNode: Released container container_1550783650344_0002_01_000002 of capacity <memory:1024, vCores:1> on host anushas-air.kc.umkc.edu:56045, which currently has 1 containers, <memory:2048, vCores:1> used and <memory:6144, vCores:7> available, release resources=true
2019-02-21 15:33:52,299 INFO org.apache.hadoop.yarn.server.resourcemanager.scheduler.AppSchedulingInfo: checking for deactivate of application :application_1550783650344_0002
2019-02-21 15:33:52,915 INFO org.apache.hadoop.yarn.server.resourcemanager.rmcontainer.RMContainerImpl: container_1550783650344_0002_01_000003 Container Transitioned from NEW to ALLOCATED
2019-02-21 15:33:52,916 INFO org.apache.hadoop.yarn.server.resourcemanager.RMAuditLogger: USER=anushamuppalla	OPERATION=AM Allocated Container	TARGET=SchedulerApp	RESULT=SUCCESS	APPID=application_1550783650344_0002	CONTAINERID=container_1550783650344_0002_01_000003
2019-02-21 15:33:52,916 INFO org.apache.hadoop.yarn.server.resourcemanager.scheduler.SchedulerNode: Assigned container container_1550783650344_0002_01_000003 of capacity <memory:1024, vCores:1> on host anushas-air.kc.umkc.edu:56045, which has 2 containers, <memory:3072, vCores:2> used and <memory:5120, vCores:6> available after allocation
2019-02-21 15:33:52,916 INFO org.apache.hadoop.yarn.server.resourcemanager.scheduler.capacity.allocator.AbstractContainerAllocator: assignedContainer application attempt=appattempt_1550783650344_0002_000001 container=container_1550783650344_0002_01_000003 queue=org.apache.hadoop.yarn.server.resourcemanager.scheduler.capacity.allocator.RegularContainerAllocator@4450a442 clusterResource=<memory:8192, vCores:8> type=OFF_SWITCH
2019-02-21 15:33:52,917 INFO org.apache.hadoop.yarn.server.resourcemanager.scheduler.capacity.ParentQueue: Re-sorting assigned queue: root.default stats: default: capacity=1.0, absoluteCapacity=1.0, usedResources=<memory:3072, vCores:2>, usedCapacity=0.375, absoluteUsedCapacity=0.375, numApps=1, numContainers=2
2019-02-21 15:33:52,918 INFO org.apache.hadoop.yarn.server.resourcemanager.scheduler.capacity.ParentQueue: assignedContainer queue=root usedCapacity=0.375 absoluteUsedCapacity=0.375 used=<memory:3072, vCores:2> cluster=<memory:8192, vCores:8>
2019-02-21 15:33:53,338 INFO org.apache.hadoop.yarn.server.resourcemanager.rmcontainer.RMContainerImpl: container_1550783650344_0002_01_000003 Container Transitioned from ALLOCATED to ACQUIRED
2019-02-21 15:33:54,350 INFO org.apache.hadoop.yarn.server.resourcemanager.rmcontainer.RMContainerImpl: container_1550783650344_0002_01_000003 Container Transitioned from ACQUIRED to RELEASED
2019-02-21 15:33:54,351 INFO org.apache.hadoop.yarn.server.resourcemanager.RMAuditLogger: USER=anushamuppalla	IP=127.0.0.1	OPERATION=AM Released Container	TARGET=SchedulerApp	RESULT=SUCCESS	APPID=application_1550783650344_0002	CONTAINERID=container_1550783650344_0002_01_000003
2019-02-21 15:33:54,351 INFO org.apache.hadoop.yarn.server.resourcemanager.scheduler.SchedulerNode: Released container container_1550783650344_0002_01_000003 of capacity <memory:1024, vCores:1> on host anushas-air.kc.umkc.edu:56045, which currently has 1 containers, <memory:2048, vCores:1> used and <memory:6144, vCores:7> available, release resources=true
2019-02-21 15:33:54,929 INFO org.apache.hadoop.yarn.server.resourcemanager.rmcontainer.RMContainerImpl: container_1550783650344_0002_01_000004 Container Transitioned from NEW to ALLOCATED
2019-02-21 15:33:54,929 INFO org.apache.hadoop.yarn.server.resourcemanager.RMAuditLogger: USER=anushamuppalla	OPERATION=AM Allocated Container	TARGET=SchedulerApp	RESULT=SUCCESS	APPID=application_1550783650344_0002	CONTAINERID=container_1550783650344_0002_01_000004
2019-02-21 15:33:54,929 INFO org.apache.hadoop.yarn.server.resourcemanager.scheduler.SchedulerNode: Assigned container container_1550783650344_0002_01_000004 of capacity <memory:1024, vCores:1> on host anushas-air.kc.umkc.edu:56045, which has 2 containers, <memory:3072, vCores:2> used and <memory:5120, vCores:6> available after allocation
2019-02-21 15:33:54,930 INFO org.apache.hadoop.yarn.server.resourcemanager.scheduler.capacity.allocator.AbstractContainerAllocator: assignedContainer application attempt=appattempt_1550783650344_0002_000001 container=container_1550783650344_0002_01_000004 queue=org.apache.hadoop.yarn.server.resourcemanager.scheduler.capacity.allocator.RegularContainerAllocator@4450a442 clusterResource=<memory:8192, vCores:8> type=OFF_SWITCH
2019-02-21 15:33:54,930 INFO org.apache.hadoop.yarn.server.resourcemanager.scheduler.capacity.ParentQueue: Re-sorting assigned queue: root.default stats: default: capacity=1.0, absoluteCapacity=1.0, usedResources=<memory:3072, vCores:2>, usedCapacity=0.375, absoluteUsedCapacity=0.375, numApps=1, numContainers=2
2019-02-21 15:33:54,930 INFO org.apache.hadoop.yarn.server.resourcemanager.scheduler.capacity.ParentQueue: assignedContainer queue=root usedCapacity=0.375 absoluteUsedCapacity=0.375 used=<memory:3072, vCores:2> cluster=<memory:8192, vCores:8>
2019-02-21 15:33:55,366 INFO org.apache.hadoop.yarn.server.resourcemanager.rmcontainer.RMContainerImpl: container_1550783650344_0002_01_000004 Container Transitioned from ALLOCATED to ACQUIRED
2019-02-21 15:33:56,383 INFO org.apache.hadoop.yarn.server.resourcemanager.rmcontainer.RMContainerImpl: container_1550783650344_0002_01_000004 Container Transitioned from ACQUIRED to RELEASED
2019-02-21 15:33:56,384 INFO org.apache.hadoop.yarn.server.resourcemanager.RMAuditLogger: USER=anushamuppalla	IP=127.0.0.1	OPERATION=AM Released Container	TARGET=SchedulerApp	RESULT=SUCCESS	APPID=application_1550783650344_0002	CONTAINERID=container_1550783650344_0002_01_000004
2019-02-21 15:33:56,385 INFO org.apache.hadoop.yarn.server.resourcemanager.scheduler.SchedulerNode: Released container container_1550783650344_0002_01_000004 of capacity <memory:1024, vCores:1> on host anushas-air.kc.umkc.edu:56045, which currently has 1 containers, <memory:2048, vCores:1> used and <memory:6144, vCores:7> available, release resources=true
2019-02-21 15:33:56,387 INFO org.apache.hadoop.yarn.server.resourcemanager.ApplicationMasterService: blacklist are updated in Scheduler.blacklistAdditions: [anushas-air.kc.umkc.edu], blacklistRemovals: []
2019-02-21 15:33:57,396 INFO org.apache.hadoop.yarn.server.resourcemanager.ApplicationMasterService: blacklist are updated in Scheduler.blacklistAdditions: [], blacklistRemovals: [anushas-air.kc.umkc.edu]
2019-02-21 15:33:57,950 INFO org.apache.hadoop.yarn.server.resourcemanager.rmcontainer.RMContainerImpl: container_1550783650344_0002_01_000005 Container Transitioned from NEW to ALLOCATED
2019-02-21 15:33:57,951 INFO org.apache.hadoop.yarn.server.resourcemanager.RMAuditLogger: USER=anushamuppalla	OPERATION=AM Allocated Container	TARGET=SchedulerApp	RESULT=SUCCESS	APPID=application_1550783650344_0002	CONTAINERID=container_1550783650344_0002_01_000005
2019-02-21 15:33:57,951 INFO org.apache.hadoop.yarn.server.resourcemanager.scheduler.SchedulerNode: Assigned container container_1550783650344_0002_01_000005 of capacity <memory:1024, vCores:1> on host anushas-air.kc.umkc.edu:56045, which has 2 containers, <memory:3072, vCores:2> used and <memory:5120, vCores:6> available after allocation
2019-02-21 15:33:57,951 INFO org.apache.hadoop.yarn.server.resourcemanager.scheduler.capacity.allocator.AbstractContainerAllocator: assignedContainer application attempt=appattempt_1550783650344_0002_000001 container=container_1550783650344_0002_01_000005 queue=org.apache.hadoop.yarn.server.resourcemanager.scheduler.capacity.allocator.RegularContainerAllocator@4450a442 clusterResource=<memory:8192, vCores:8> type=OFF_SWITCH
2019-02-21 15:33:57,951 INFO org.apache.hadoop.yarn.server.resourcemanager.scheduler.capacity.ParentQueue: Re-sorting assigned queue: root.default stats: default: capacity=1.0, absoluteCapacity=1.0, usedResources=<memory:3072, vCores:2>, usedCapacity=0.375, absoluteUsedCapacity=0.375, numApps=1, numContainers=2
2019-02-21 15:33:57,952 INFO org.apache.hadoop.yarn.server.resourcemanager.scheduler.capacity.ParentQueue: assignedContainer queue=root usedCapacity=0.375 absoluteUsedCapacity=0.375 used=<memory:3072, vCores:2> cluster=<memory:8192, vCores:8>
2019-02-21 15:33:58,412 INFO org.apache.hadoop.yarn.server.resourcemanager.rmcontainer.RMContainerImpl: container_1550783650344_0002_01_000005 Container Transitioned from ALLOCATED to ACQUIRED
2019-02-21 15:33:58,959 INFO org.apache.hadoop.yarn.server.resourcemanager.rmapp.attempt.RMAppAttemptImpl: Updating application attempt appattempt_1550783650344_0002_000001 with final state: FINISHING, and exit status: -1000
2019-02-21 15:33:58,959 INFO org.apache.hadoop.yarn.server.resourcemanager.rmapp.attempt.RMAppAttemptImpl: appattempt_1550783650344_0002_000001 State change from RUNNING to FINAL_SAVING
2019-02-21 15:33:58,959 INFO org.apache.hadoop.yarn.server.resourcemanager.rmapp.RMAppImpl: Updating application application_1550783650344_0002 with final state: FINISHING
2019-02-21 15:33:58,959 INFO org.apache.hadoop.yarn.server.resourcemanager.rmapp.RMAppImpl: application_1550783650344_0002 State change from RUNNING to FINAL_SAVING on event=ATTEMPT_UNREGISTERED
2019-02-21 15:33:58,959 INFO org.apache.hadoop.yarn.server.resourcemanager.recovery.RMStateStore: Updating info for app: application_1550783650344_0002
2019-02-21 15:33:58,960 INFO org.apache.hadoop.yarn.server.resourcemanager.rmapp.attempt.RMAppAttemptImpl: appattempt_1550783650344_0002_000001 State change from FINAL_SAVING to FINISHING
2019-02-21 15:33:58,960 INFO org.apache.hadoop.yarn.server.resourcemanager.rmapp.RMAppImpl: application_1550783650344_0002 State change from FINAL_SAVING to FINISHING on event=APP_UPDATE_SAVED
2019-02-21 15:33:59,966 INFO org.apache.hadoop.yarn.server.resourcemanager.ApplicationMasterService: application_1550783650344_0002 unregistered successfully. 
2019-02-21 15:34:05,354 INFO org.apache.hadoop.yarn.server.resourcemanager.rmcontainer.RMContainerImpl: container_1550783650344_0002_01_000001 Container Transitioned from RUNNING to COMPLETED
2019-02-21 15:34:05,355 INFO org.apache.hadoop.yarn.server.resourcemanager.ApplicationMasterService: Unregistering app attempt : appattempt_1550783650344_0002_000001
2019-02-21 15:34:05,355 INFO org.apache.hadoop.yarn.server.resourcemanager.RMAuditLogger: USER=anushamuppalla	OPERATION=AM Released Container	TARGET=SchedulerApp	RESULT=SUCCESS	APPID=application_1550783650344_0002	CONTAINERID=container_1550783650344_0002_01_000001
2019-02-21 15:34:05,355 INFO org.apache.hadoop.yarn.server.resourcemanager.security.AMRMTokenSecretManager: Application finished, removing password for appattempt_1550783650344_0002_000001
2019-02-21 15:34:05,356 INFO org.apache.hadoop.yarn.server.resourcemanager.rmapp.attempt.RMAppAttemptImpl: appattempt_1550783650344_0002_000001 State change from FINISHING to FINISHED
2019-02-21 15:34:05,356 INFO org.apache.hadoop.yarn.server.resourcemanager.scheduler.SchedulerNode: Released container container_1550783650344_0002_01_000001 of capacity <memory:2048, vCores:1> on host anushas-air.kc.umkc.edu:56045, which currently has 1 containers, <memory:1024, vCores:1> used and <memory:7168, vCores:7> available, release resources=true
2019-02-21 15:34:05,356 INFO org.apache.hadoop.yarn.server.resourcemanager.rmapp.RMAppImpl: application_1550783650344_0002 State change from FINISHING to FINISHED on event=ATTEMPT_FINISHED
2019-02-21 15:34:05,356 INFO org.apache.hadoop.yarn.server.resourcemanager.scheduler.capacity.CapacityScheduler: Application Attempt appattempt_1550783650344_0002_000001 is done. finalState=FINISHED
2019-02-21 15:34:05,356 INFO org.apache.hadoop.yarn.server.resourcemanager.RMAuditLogger: USER=anushamuppalla	OPERATION=Application Finished - Succeeded	TARGET=RMAppManager	RESULT=SUCCESS	APPID=application_1550783650344_0002
2019-02-21 15:34:05,357 INFO org.apache.hadoop.yarn.server.resourcemanager.rmcontainer.RMContainerImpl: container_1550783650344_0002_01_000005 Container Transitioned from ACQUIRED to KILLED
2019-02-21 15:34:05,357 INFO org.apache.hadoop.yarn.server.resourcemanager.RMAuditLogger: USER=anushamuppalla	OPERATION=AM Released Container	TARGET=SchedulerApp	RESULT=SUCCESS	APPID=application_1550783650344_0002	CONTAINERID=container_1550783650344_0002_01_000005
2019-02-21 15:34:05,357 INFO org.apache.hadoop.yarn.server.resourcemanager.scheduler.SchedulerNode: Released container container_1550783650344_0002_01_000005 of capacity <memory:1024, vCores:1> on host anushas-air.kc.umkc.edu:56045, which currently has 0 containers, <memory:0, vCores:0> used and <memory:8192, vCores:8> available, release resources=true
2019-02-21 15:34:05,357 INFO org.apache.hadoop.yarn.server.resourcemanager.amlauncher.AMLauncher: Cleaning master appattempt_1550783650344_0002_000001
2019-02-21 15:34:05,359 INFO org.apache.hadoop.yarn.server.resourcemanager.scheduler.AppSchedulingInfo: Application application_1550783650344_0002 requests cleared
2019-02-21 15:34:05,360 INFO org.apache.hadoop.yarn.server.resourcemanager.scheduler.capacity.LeafQueue: Application removed - appId: application_1550783650344_0002 user: anushamuppalla queue: default #user-pending-applications: 0 #user-active-applications: 0 #queue-pending-applications: 0 #queue-active-applications: 0
2019-02-21 15:34:05,360 INFO org.apache.hadoop.yarn.server.resourcemanager.RMAppManager$ApplicationSummary: appId=application_1550783650344_0002,name=word count,user=anushamuppalla,queue=default,state=FINISHED,trackingUrl=http://anushas-air.kc.umkc.edu:8088/proxy/application_1550783650344_0002/,appMasterHost=anushas-air.kc.umkc.edu,startTime=1550784811043,finishTime=1550784838959,finalStatus=FAILED,memorySeconds=73084,vcoreSeconds=36,preemptedMemorySeconds=0,preemptedVcoreSeconds=0,preemptedAMContainers=0,preemptedNonAMContainers=0,preemptedResources=<memory:0\, vCores:0>,applicationType=MAPREDUCE
2019-02-21 15:34:05,361 INFO org.apache.hadoop.yarn.server.resourcemanager.scheduler.capacity.ParentQueue: Application removed - appId: application_1550783650344_0002 user: anushamuppalla leaf-queue of parent: root #applications: 0
2019-02-21 15:37:11,691 WARN org.apache.hadoop.util.JvmPauseMonitor: Detected pause in JVM or host machine (eg GC): pause of approximately 25178ms
No GCs detected
2019-02-21 15:40:34,411 ERROR org.apache.hadoop.yarn.server.resourcemanager.ResourceManager: RECEIVED SIGNAL 15: SIGTERM
2019-02-21 15:40:34,424 ERROR org.apache.hadoop.security.token.delegation.AbstractDelegationTokenSecretManager: ExpiredTokenRemover received java.lang.InterruptedException: sleep interrupted
2019-02-21 15:40:34,428 INFO org.mortbay.log: Stopped HttpServer2$SelectChannelConnectorWithSafeStartup@localhost:8088
2019-02-21 15:40:34,540 INFO org.apache.hadoop.ipc.Server: Stopping server on 8032
2019-02-21 15:40:34,547 INFO org.apache.hadoop.ipc.Server: Stopping IPC Server listener on 8032
2019-02-21 15:40:34,548 INFO org.apache.hadoop.ipc.Server: Stopping IPC Server Responder
2019-02-21 15:40:34,554 INFO org.apache.hadoop.ipc.Server: Stopping server on 8033
2019-02-21 15:40:34,556 INFO org.apache.hadoop.ipc.Server: Stopping IPC Server listener on 8033
2019-02-21 15:40:34,557 INFO org.apache.hadoop.ipc.Server: Stopping IPC Server Responder
2019-02-21 15:40:34,559 INFO org.apache.hadoop.yarn.server.resourcemanager.ResourceManager: Transitioning to standby state
2019-02-21 15:40:34,560 WARN org.apache.hadoop.yarn.server.resourcemanager.amlauncher.ApplicationMasterLauncher: org.apache.hadoop.yarn.server.resourcemanager.amlauncher.ApplicationMasterLauncher$LauncherThread interrupted. Returning.
2019-02-21 15:40:34,564 INFO org.apache.hadoop.ipc.Server: Stopping server on 8030
2019-02-21 15:40:34,568 INFO org.apache.hadoop.ipc.Server: Stopping IPC Server listener on 8030
2019-02-21 15:40:34,569 INFO org.apache.hadoop.ipc.Server: Stopping IPC Server Responder
2019-02-21 15:40:34,569 INFO org.apache.hadoop.ipc.Server: Stopping server on 8031
2019-02-21 15:40:34,572 INFO org.apache.hadoop.ipc.Server: Stopping IPC Server listener on 8031
2019-02-21 15:40:34,573 INFO org.apache.hadoop.ipc.Server: Stopping IPC Server Responder
2019-02-21 15:40:34,573 INFO org.apache.hadoop.yarn.util.AbstractLivelinessMonitor: NMLivelinessMonitor thread interrupted
2019-02-21 15:40:34,575 ERROR org.apache.hadoop.yarn.server.resourcemanager.ResourceManager: Returning, interrupted : java.lang.InterruptedException
2019-02-21 15:40:34,577 INFO org.apache.hadoop.yarn.event.AsyncDispatcher: AsyncDispatcher is draining to stop, igonring any new events.
2019-02-21 15:40:34,578 INFO org.apache.hadoop.yarn.util.AbstractLivelinessMonitor: AMLivelinessMonitor thread interrupted
2019-02-21 15:40:34,579 INFO org.apache.hadoop.yarn.util.AbstractLivelinessMonitor: AMLivelinessMonitor thread interrupted
2019-02-21 15:40:34,580 INFO org.apache.hadoop.yarn.util.AbstractLivelinessMonitor: org.apache.hadoop.yarn.server.resourcemanager.rmcontainer.ContainerAllocationExpirer thread interrupted
2019-02-21 15:40:34,580 ERROR org.apache.hadoop.security.token.delegation.AbstractDelegationTokenSecretManager: ExpiredTokenRemover received java.lang.InterruptedException: sleep interrupted
2019-02-21 15:40:34,582 INFO org.apache.hadoop.metrics2.impl.MetricsSystemImpl: Stopping ResourceManager metrics system...
2019-02-21 15:40:34,584 INFO org.apache.hadoop.metrics2.impl.MetricsSystemImpl: ResourceManager metrics system stopped.
2019-02-21 15:40:34,585 INFO org.apache.hadoop.metrics2.impl.MetricsSystemImpl: ResourceManager metrics system shutdown complete.
2019-02-21 15:40:34,585 INFO org.apache.hadoop.yarn.event.AsyncDispatcher: AsyncDispatcher is draining to stop, igonring any new events.
2019-02-21 15:40:34,585 INFO org.apache.hadoop.yarn.server.resourcemanager.ResourceManager: Transitioned to standby state
2019-02-21 15:40:34,585 INFO org.apache.hadoop.yarn.server.resourcemanager.ResourceManager: SHUTDOWN_MSG: 
/************************************************************
SHUTDOWN_MSG: Shutting down ResourceManager at ANUSHAs-Air.kc.umkc.edu/10.205.2.163
************************************************************/
2019-02-21 15:41:17,628 INFO org.apache.hadoop.yarn.server.resourcemanager.ResourceManager: STARTUP_MSG: 
/************************************************************
STARTUP_MSG: Starting ResourceManager
STARTUP_MSG:   user = anushamuppalla
STARTUP_MSG:   host = ANUSHAs-Air.kc.umkc.edu/10.205.2.163
STARTUP_MSG:   args = []
STARTUP_MSG:   version = 2.8.1
STARTUP_MSG:   build = https://git-wip-us.apache.org/repos/asf/hadoop.git -r 20fe5304904fc2f5a18053c389e43cd26f7a70fe; compiled by 'vinodkv' on 2017-06-02T06:14Z
STARTUP_MSG:   java = 11.0.2
************************************************************/
2019-02-21 15:41:17,636 INFO org.apache.hadoop.yarn.server.resourcemanager.ResourceManager: registered UNIX signal handlers for [TERM, HUP, INT]
2019-02-21 15:41:17,989 INFO org.apache.hadoop.conf.Configuration: found resource core-site.xml at file:/Users/anushamuppalla/hadoop-2.8.1/etc/hadoop/core-site.xml
2019-02-21 15:41:18,027 WARN org.apache.hadoop.util.NativeCodeLoader: Unable to load native-hadoop library for your platform... using builtin-java classes where applicable
2019-02-21 15:41:18,051 INFO org.apache.hadoop.security.Groups: clearing userToGroupsMap cache
2019-02-21 15:41:18,142 INFO org.apache.hadoop.conf.Configuration: found resource yarn-site.xml at file:/Users/anushamuppalla/hadoop-2.8.1/etc/hadoop/yarn-site.xml
2019-02-21 15:41:18,535 INFO org.apache.hadoop.yarn.event.AsyncDispatcher: Registering class org.apache.hadoop.yarn.server.resourcemanager.RMFatalEventType for class org.apache.hadoop.yarn.server.resourcemanager.ResourceManager$RMFatalEventDispatcher
2019-02-21 15:41:18,664 INFO org.apache.hadoop.yarn.server.resourcemanager.security.NMTokenSecretManagerInRM: NMTokenKeyRollingInterval: 86400000ms and NMTokenKeyActivationDelay: 900000ms
2019-02-21 15:41:18,671 INFO org.apache.hadoop.yarn.server.resourcemanager.security.RMContainerTokenSecretManager: ContainerTokenKeyRollingInterval: 86400000ms and ContainerTokenKeyActivationDelay: 900000ms
2019-02-21 15:41:18,684 INFO org.apache.hadoop.yarn.server.resourcemanager.security.AMRMTokenSecretManager: AMRMTokenKeyRollingInterval: 86400000ms and AMRMTokenKeyActivationDelay: 900000 ms
2019-02-21 15:41:18,741 INFO org.apache.hadoop.yarn.event.AsyncDispatcher: Registering class org.apache.hadoop.yarn.server.resourcemanager.recovery.RMStateStoreEventType for class org.apache.hadoop.yarn.server.resourcemanager.recovery.RMStateStore$ForwardingEventHandler
2019-02-21 15:41:18,745 INFO org.apache.hadoop.yarn.event.AsyncDispatcher: Registering class org.apache.hadoop.yarn.server.resourcemanager.NodesListManagerEventType for class org.apache.hadoop.yarn.server.resourcemanager.NodesListManager
2019-02-21 15:41:18,745 INFO org.apache.hadoop.yarn.server.resourcemanager.ResourceManager: Using Scheduler: org.apache.hadoop.yarn.server.resourcemanager.scheduler.capacity.CapacityScheduler
2019-02-21 15:41:18,786 INFO org.apache.hadoop.yarn.event.AsyncDispatcher: Registering class org.apache.hadoop.yarn.server.resourcemanager.scheduler.event.SchedulerEventType for class org.apache.hadoop.yarn.server.resourcemanager.ResourceManager$SchedulerEventDispatcher
2019-02-21 15:41:18,790 INFO org.apache.hadoop.yarn.event.AsyncDispatcher: Registering class org.apache.hadoop.yarn.server.resourcemanager.rmapp.RMAppEventType for class org.apache.hadoop.yarn.server.resourcemanager.ResourceManager$ApplicationEventDispatcher
2019-02-21 15:41:18,792 INFO org.apache.hadoop.yarn.event.AsyncDispatcher: Registering class org.apache.hadoop.yarn.server.resourcemanager.rmapp.attempt.RMAppAttemptEventType for class org.apache.hadoop.yarn.server.resourcemanager.ResourceManager$ApplicationAttemptEventDispatcher
2019-02-21 15:41:18,793 INFO org.apache.hadoop.yarn.event.AsyncDispatcher: Registering class org.apache.hadoop.yarn.server.resourcemanager.rmnode.RMNodeEventType for class org.apache.hadoop.yarn.server.resourcemanager.ResourceManager$NodeEventDispatcher
2019-02-21 15:41:18,866 INFO org.apache.hadoop.metrics2.impl.MetricsConfig: loaded properties from hadoop-metrics2.properties
2019-02-21 15:41:19,049 INFO org.apache.hadoop.metrics2.impl.MetricsSystemImpl: Scheduled Metric snapshot period at 10 second(s).
2019-02-21 15:41:19,049 INFO org.apache.hadoop.metrics2.impl.MetricsSystemImpl: ResourceManager metrics system started
2019-02-21 15:41:19,154 INFO org.apache.hadoop.yarn.event.AsyncDispatcher: Registering class org.apache.hadoop.yarn.server.resourcemanager.RMAppManagerEventType for class org.apache.hadoop.yarn.server.resourcemanager.RMAppManager
2019-02-21 15:41:19,187 INFO org.apache.hadoop.yarn.event.AsyncDispatcher: Registering class org.apache.hadoop.yarn.server.resourcemanager.amlauncher.AMLauncherEventType for class org.apache.hadoop.yarn.server.resourcemanager.amlauncher.ApplicationMasterLauncher
2019-02-21 15:41:19,192 INFO org.apache.hadoop.yarn.server.resourcemanager.RMNMInfo: Registered RMNMInfo MBean
2019-02-21 15:41:19,214 INFO org.apache.hadoop.yarn.security.YarnAuthorizationProvider: org.apache.hadoop.yarn.security.ConfiguredYarnAuthorizer is instiantiated.
2019-02-21 15:41:19,215 INFO org.apache.hadoop.util.HostsFileReader: Refreshing hosts (include/exclude) list
2019-02-21 15:41:19,233 INFO org.apache.hadoop.conf.Configuration: found resource capacity-scheduler.xml at file:/Users/anushamuppalla/hadoop-2.8.1/etc/hadoop/capacity-scheduler.xml
2019-02-21 15:41:19,315 INFO org.apache.hadoop.yarn.server.resourcemanager.scheduler.capacity.CapacitySchedulerConfiguration: max alloc mb per queue for root is undefined
2019-02-21 15:41:19,315 INFO org.apache.hadoop.yarn.server.resourcemanager.scheduler.capacity.CapacitySchedulerConfiguration: max alloc vcore per queue for root is undefined
2019-02-21 15:41:19,328 INFO org.apache.hadoop.yarn.server.resourcemanager.scheduler.capacity.ParentQueue: root, capacity=1.0, asboluteCapacity=1.0, maxCapacity=1.0, asboluteMaxCapacity=1.0, state=RUNNING, acls=SUBMIT_APP:*ADMINISTER_QUEUE:*, labels=*,, offswitchPerHeartbeatLimit = 1, reservationsContinueLooking=true
2019-02-21 15:41:19,328 INFO org.apache.hadoop.yarn.server.resourcemanager.scheduler.capacity.ParentQueue: Initialized parent-queue root name=root, fullname=root
2019-02-21 15:41:19,345 INFO org.apache.hadoop.yarn.server.resourcemanager.scheduler.capacity.CapacitySchedulerConfiguration: max alloc mb per queue for root.default is undefined
2019-02-21 15:41:19,345 INFO org.apache.hadoop.yarn.server.resourcemanager.scheduler.capacity.CapacitySchedulerConfiguration: max alloc vcore per queue for root.default is undefined
2019-02-21 15:41:19,348 INFO org.apache.hadoop.yarn.server.resourcemanager.scheduler.capacity.LeafQueue: Initializing default
capacity = 1.0 [= (float) configuredCapacity / 100 ]
asboluteCapacity = 1.0 [= parentAbsoluteCapacity * capacity ]
maxCapacity = 1.0 [= configuredMaxCapacity ]
absoluteMaxCapacity = 1.0 [= 1.0 maximumCapacity undefined, (parentAbsoluteMaxCapacity * maximumCapacity) / 100 otherwise ]
userLimit = 100 [= configuredUserLimit ]
userLimitFactor = 1.0 [= configuredUserLimitFactor ]
maxApplications = 10000 [= configuredMaximumSystemApplicationsPerQueue or (int)(configuredMaximumSystemApplications * absoluteCapacity)]
maxApplicationsPerUser = 10000 [= (int)(maxApplications * (userLimit / 100.0f) * userLimitFactor) ]
usedCapacity = 0.0 [= usedResourcesMemory / (clusterResourceMemory * absoluteCapacity)]
absoluteUsedCapacity = 0.0 [= usedResourcesMemory / clusterResourceMemory]
maxAMResourcePerQueuePercent = 0.1 [= configuredMaximumAMResourcePercent ]
minimumAllocationFactor = 0.875 [= (float)(maximumAllocationMemory - minimumAllocationMemory) / maximumAllocationMemory ]
maximumAllocation = <memory:8192, vCores:4> [= configuredMaxAllocation ]
numContainers = 0 [= currentNumContainers ]
state = RUNNING [= configuredState ]
acls = SUBMIT_APP:*ADMINISTER_QUEUE:* [= configuredAcls ]
nodeLocalityDelay = 40
labels=*,
reservationsContinueLooking = true
preemptionDisabled = true
defaultAppPriorityPerQueue = 0
2019-02-21 15:41:19,348 INFO org.apache.hadoop.yarn.server.resourcemanager.scheduler.capacity.CapacityScheduler: Initialized queue: default: capacity=1.0, absoluteCapacity=1.0, usedResources=<memory:0, vCores:0>, usedCapacity=0.0, absoluteUsedCapacity=0.0, numApps=0, numContainers=0
2019-02-21 15:41:19,349 INFO org.apache.hadoop.yarn.server.resourcemanager.scheduler.capacity.CapacityScheduler: Initialized queue: root: numChildQueue= 1, capacity=1.0, absoluteCapacity=1.0, usedResources=<memory:0, vCores:0>usedCapacity=0.0, numApps=0, numContainers=0
2019-02-21 15:41:19,349 INFO org.apache.hadoop.yarn.server.resourcemanager.scheduler.capacity.CapacityScheduler: Initialized root queue root: numChildQueue= 1, capacity=1.0, absoluteCapacity=1.0, usedResources=<memory:0, vCores:0>usedCapacity=0.0, numApps=0, numContainers=0
2019-02-21 15:41:19,350 INFO org.apache.hadoop.yarn.server.resourcemanager.scheduler.capacity.CapacityScheduler: Initialized queue mappings, override: false
2019-02-21 15:41:19,354 INFO org.apache.hadoop.yarn.server.resourcemanager.scheduler.capacity.CapacityScheduler: Initialized CapacityScheduler with calculator=class org.apache.hadoop.yarn.util.resource.DefaultResourceCalculator, minimumAllocation=<<memory:1024, vCores:1>>, maximumAllocation=<<memory:8192, vCores:4>>, asynchronousScheduling=false, asyncScheduleInterval=5ms
2019-02-21 15:41:19,359 INFO org.apache.hadoop.conf.Configuration: dynamic-resources.xml not found
2019-02-21 15:41:19,389 INFO org.apache.hadoop.yarn.server.resourcemanager.metrics.SystemMetricsPublisher: YARN system metrics publishing service is not enabled
2019-02-21 15:41:19,389 INFO org.apache.hadoop.yarn.server.resourcemanager.ResourceManager: Transitioning to active state
2019-02-21 15:41:19,410 INFO org.apache.hadoop.util.JvmPauseMonitor: Starting JVM pause monitor
2019-02-21 15:41:19,435 INFO org.apache.hadoop.yarn.server.resourcemanager.recovery.RMStateStore: Updating AMRMToken
2019-02-21 15:41:19,435 INFO org.apache.hadoop.yarn.server.resourcemanager.security.RMContainerTokenSecretManager: Rolling master-key for container-tokens
2019-02-21 15:41:19,436 INFO org.apache.hadoop.yarn.server.resourcemanager.security.NMTokenSecretManagerInRM: Rolling master-key for nm-tokens
2019-02-21 15:41:19,436 INFO org.apache.hadoop.security.token.delegation.AbstractDelegationTokenSecretManager: Updating the current master key for generating delegation tokens
2019-02-21 15:41:19,437 INFO org.apache.hadoop.yarn.server.resourcemanager.security.RMDelegationTokenSecretManager: storing master key with keyID 1
2019-02-21 15:41:19,437 INFO org.apache.hadoop.yarn.server.resourcemanager.recovery.RMStateStore: Storing RMDTMasterKey.
2019-02-21 15:41:19,439 INFO org.apache.hadoop.security.token.delegation.AbstractDelegationTokenSecretManager: Starting expired delegation token remover thread, tokenRemoverScanInterval=60 min(s)
2019-02-21 15:41:19,440 INFO org.apache.hadoop.security.token.delegation.AbstractDelegationTokenSecretManager: Updating the current master key for generating delegation tokens
2019-02-21 15:41:19,440 INFO org.apache.hadoop.yarn.server.resourcemanager.security.RMDelegationTokenSecretManager: storing master key with keyID 2
2019-02-21 15:41:19,441 INFO org.apache.hadoop.yarn.server.resourcemanager.recovery.RMStateStore: Storing RMDTMasterKey.
2019-02-21 15:41:19,446 INFO org.apache.hadoop.yarn.event.AsyncDispatcher: Registering class org.apache.hadoop.yarn.nodelabels.event.NodeLabelsStoreEventType for class org.apache.hadoop.yarn.nodelabels.CommonNodeLabelsManager$ForwardingEventHandler
2019-02-21 15:41:19,496 INFO org.apache.hadoop.ipc.CallQueueManager: Using callQueue: class java.util.concurrent.LinkedBlockingQueue queueCapacity: 5000 scheduler: class org.apache.hadoop.ipc.DefaultRpcScheduler
2019-02-21 15:41:19,555 INFO org.apache.hadoop.ipc.Server: Starting Socket Reader #1 for port 8031
2019-02-21 15:41:19,872 INFO org.apache.hadoop.yarn.factories.impl.pb.RpcServerFactoryPBImpl: Adding protocol org.apache.hadoop.yarn.server.api.ResourceTrackerPB to the server
2019-02-21 15:41:19,874 INFO org.apache.hadoop.ipc.Server: IPC Server Responder: starting
2019-02-21 15:41:19,874 INFO org.apache.hadoop.ipc.Server: IPC Server listener on 8031: starting
2019-02-21 15:41:19,932 INFO org.apache.hadoop.ipc.CallQueueManager: Using callQueue: class java.util.concurrent.LinkedBlockingQueue queueCapacity: 5000 scheduler: class org.apache.hadoop.ipc.DefaultRpcScheduler
2019-02-21 15:41:19,940 INFO org.apache.hadoop.ipc.Server: Starting Socket Reader #1 for port 8030
2019-02-21 15:41:19,956 INFO org.apache.hadoop.yarn.factories.impl.pb.RpcServerFactoryPBImpl: Adding protocol org.apache.hadoop.yarn.api.ApplicationMasterProtocolPB to the server
2019-02-21 15:41:19,957 INFO org.apache.hadoop.ipc.Server: IPC Server Responder: starting
2019-02-21 15:41:19,958 INFO org.apache.hadoop.ipc.Server: IPC Server listener on 8030: starting
2019-02-21 15:41:20,173 INFO org.apache.hadoop.ipc.CallQueueManager: Using callQueue: class java.util.concurrent.LinkedBlockingQueue queueCapacity: 5000 scheduler: class org.apache.hadoop.ipc.DefaultRpcScheduler
2019-02-21 15:41:20,174 INFO org.apache.hadoop.ipc.Server: Starting Socket Reader #1 for port 8032
2019-02-21 15:41:20,181 INFO org.apache.hadoop.yarn.factories.impl.pb.RpcServerFactoryPBImpl: Adding protocol org.apache.hadoop.yarn.api.ApplicationClientProtocolPB to the server
2019-02-21 15:41:20,182 INFO org.apache.hadoop.ipc.Server: IPC Server Responder: starting
2019-02-21 15:41:20,182 INFO org.apache.hadoop.ipc.Server: IPC Server listener on 8032: starting
2019-02-21 15:41:20,193 INFO org.apache.hadoop.yarn.server.resourcemanager.ResourceManager: Transitioned to active state
2019-02-21 15:41:20,339 INFO org.mortbay.log: Logging to org.slf4j.impl.Log4jLoggerAdapter(org.mortbay.log) via org.mortbay.log.Slf4jLog
2019-02-21 15:41:20,352 INFO org.apache.hadoop.security.authentication.server.AuthenticationFilter: Unable to initialize FileSignerSecretProvider, falling back to use random secrets.
2019-02-21 15:41:20,360 INFO org.apache.hadoop.http.HttpRequestLog: Http request log for http.requests.resourcemanager is not defined
2019-02-21 15:41:20,389 INFO org.apache.hadoop.http.HttpServer2: Added global filter 'safety' (class=org.apache.hadoop.http.HttpServer2$QuotingInputFilter)
2019-02-21 15:41:20,397 INFO org.apache.hadoop.http.HttpServer2: Added filter RMAuthenticationFilter (class=org.apache.hadoop.yarn.server.security.http.RMAuthenticationFilter) to context cluster
2019-02-21 15:41:20,398 INFO org.apache.hadoop.http.HttpServer2: Added filter RMAuthenticationFilter (class=org.apache.hadoop.yarn.server.security.http.RMAuthenticationFilter) to context logs
2019-02-21 15:41:20,398 INFO org.apache.hadoop.http.HttpServer2: Added filter RMAuthenticationFilter (class=org.apache.hadoop.yarn.server.security.http.RMAuthenticationFilter) to context static
2019-02-21 15:41:20,398 INFO org.apache.hadoop.http.HttpServer2: Added filter static_user_filter (class=org.apache.hadoop.http.lib.StaticUserWebFilter$StaticUserFilter) to context cluster
2019-02-21 15:41:20,398 INFO org.apache.hadoop.http.HttpServer2: Added filter static_user_filter (class=org.apache.hadoop.http.lib.StaticUserWebFilter$StaticUserFilter) to context logs
2019-02-21 15:41:20,398 INFO org.apache.hadoop.http.HttpServer2: Added filter static_user_filter (class=org.apache.hadoop.http.lib.StaticUserWebFilter$StaticUserFilter) to context static
2019-02-21 15:41:20,402 INFO org.apache.hadoop.http.HttpServer2: adding path spec: /cluster/*
2019-02-21 15:41:20,402 INFO org.apache.hadoop.http.HttpServer2: adding path spec: /ws/*
2019-02-21 15:41:21,166 INFO org.apache.hadoop.yarn.webapp.WebApps: Registered webapp guice modules
2019-02-21 15:41:21,174 INFO org.apache.hadoop.http.HttpServer2: Jetty bound to port 8088
2019-02-21 15:41:21,174 INFO org.mortbay.log: jetty-6.1.26
2019-02-21 15:41:21,262 INFO org.mortbay.log: Extract jar:file:/Users/anushamuppalla/hadoop-2.8.1/share/hadoop/yarn/hadoop-yarn-common-2.8.1.jar!/webapps/cluster to /var/folders/w5/msff5yg55hvgnrf5gxk_qk680000gn/T/Jetty_localhost_8088_cluster____.3j26f5/webapp
2019-02-21 15:41:21,450 INFO org.apache.hadoop.security.token.delegation.AbstractDelegationTokenSecretManager: Updating the current master key for generating delegation tokens
2019-02-21 15:41:21,450 INFO org.apache.hadoop.security.token.delegation.AbstractDelegationTokenSecretManager: Starting expired delegation token remover thread, tokenRemoverScanInterval=60 min(s)
2019-02-21 15:41:21,451 INFO org.apache.hadoop.security.token.delegation.AbstractDelegationTokenSecretManager: Updating the current master key for generating delegation tokens
2019-02-21 15:41:23,095 INFO org.mortbay.log: Started HttpServer2$SelectChannelConnectorWithSafeStartup@localhost:8088
2019-02-21 15:41:23,095 INFO org.apache.hadoop.yarn.webapp.WebApps: Web app cluster started at 8088
2019-02-21 15:41:23,141 INFO org.apache.hadoop.ipc.CallQueueManager: Using callQueue: class java.util.concurrent.LinkedBlockingQueue queueCapacity: 100 scheduler: class org.apache.hadoop.ipc.DefaultRpcScheduler
2019-02-21 15:41:23,141 INFO org.apache.hadoop.ipc.Server: Starting Socket Reader #1 for port 8033
2019-02-21 15:41:23,145 INFO org.apache.hadoop.yarn.factories.impl.pb.RpcServerFactoryPBImpl: Adding protocol org.apache.hadoop.yarn.server.api.ResourceManagerAdministrationProtocolPB to the server
2019-02-21 15:41:23,146 INFO org.apache.hadoop.ipc.Server: IPC Server Responder: starting
2019-02-21 15:41:23,146 INFO org.apache.hadoop.ipc.Server: IPC Server listener on 8033: starting
2019-02-21 15:41:24,373 INFO org.apache.hadoop.yarn.server.resourcemanager.ResourceTrackerService: NodeManager from node anushas-air.kc.umkc.edu(cmPort: 56365 httpPort: 8042) registered with capability: <memory:8192, vCores:8>, assigned nodeId anushas-air.kc.umkc.edu:56365
2019-02-21 15:41:24,380 INFO org.apache.hadoop.yarn.server.resourcemanager.rmnode.RMNodeImpl: anushas-air.kc.umkc.edu:56365 Node Transitioned from NEW to RUNNING
2019-02-21 15:41:24,389 INFO org.apache.hadoop.yarn.server.resourcemanager.scheduler.capacity.CapacityScheduler: Added node anushas-air.kc.umkc.edu:56365 clusterResource: <memory:8192, vCores:8>
2019-02-21 15:42:54,190 INFO org.apache.hadoop.yarn.server.resourcemanager.ClientRMService: Allocated new applicationId: 1
2019-02-21 15:42:55,682 INFO org.apache.hadoop.yarn.server.resourcemanager.scheduler.capacity.CapacityScheduler: Application 'application_1550785279390_0001' is submitted without priority hence considering default queue/cluster priority: 0
2019-02-21 15:42:55,682 INFO org.apache.hadoop.yarn.server.resourcemanager.scheduler.capacity.CapacityScheduler: Priority '0' is acceptable in queue : default for application: application_1550785279390_0001 for the user: anushamuppalla
2019-02-21 15:42:55,706 INFO org.apache.hadoop.yarn.server.resourcemanager.ClientRMService: Application with id 1 submitted by user anushamuppalla
2019-02-21 15:42:55,706 INFO org.apache.hadoop.yarn.server.resourcemanager.rmapp.RMAppImpl: Storing application with id application_1550785279390_0001
2019-02-21 15:42:55,709 INFO org.apache.hadoop.yarn.server.resourcemanager.RMAuditLogger: USER=anushamuppalla	IP=127.0.0.1	OPERATION=Submit Application Request	TARGET=ClientRMService	RESULT=SUCCESS	APPID=application_1550785279390_0001
2019-02-21 15:42:55,717 INFO org.apache.hadoop.yarn.server.resourcemanager.rmapp.RMAppImpl: application_1550785279390_0001 State change from NEW to NEW_SAVING on event=START
2019-02-21 15:42:55,717 INFO org.apache.hadoop.yarn.server.resourcemanager.recovery.RMStateStore: Storing info for app: application_1550785279390_0001
2019-02-21 15:42:55,717 INFO org.apache.hadoop.yarn.server.resourcemanager.rmapp.RMAppImpl: application_1550785279390_0001 State change from NEW_SAVING to SUBMITTED on event=APP_NEW_SAVED
2019-02-21 15:42:55,719 INFO org.apache.hadoop.yarn.server.resourcemanager.scheduler.capacity.ParentQueue: Application added - appId: application_1550785279390_0001 user: anushamuppalla leaf-queue of parent: root #applications: 1
2019-02-21 15:42:55,720 INFO org.apache.hadoop.yarn.server.resourcemanager.scheduler.capacity.CapacityScheduler: Accepted application application_1550785279390_0001 from user: anushamuppalla, in queue: default
2019-02-21 15:42:55,737 INFO org.apache.hadoop.yarn.server.resourcemanager.rmapp.RMAppImpl: application_1550785279390_0001 State change from SUBMITTED to ACCEPTED on event=APP_ACCEPTED
2019-02-21 15:42:55,773 INFO org.apache.hadoop.yarn.server.resourcemanager.ApplicationMasterService: Registering app attempt : appattempt_1550785279390_0001_000001
2019-02-21 15:42:55,774 INFO org.apache.hadoop.yarn.server.resourcemanager.rmapp.attempt.RMAppAttemptImpl: appattempt_1550785279390_0001_000001 State change from NEW to SUBMITTED
2019-02-21 15:42:55,813 WARN org.apache.hadoop.yarn.server.resourcemanager.scheduler.capacity.LeafQueue: maximum-am-resource-percent is insufficient to start a single application in queue, it is likely set too low. skipping enforcement to allow at least one application to start
2019-02-21 15:42:55,814 WARN org.apache.hadoop.yarn.server.resourcemanager.scheduler.capacity.LeafQueue: maximum-am-resource-percent is insufficient to start a single application in queue for user, it is likely set too low. skipping enforcement to allow at least one application to start
2019-02-21 15:42:55,816 INFO org.apache.hadoop.yarn.server.resourcemanager.scheduler.capacity.LeafQueue: Application application_1550785279390_0001 from user: anushamuppalla activated in queue: default
2019-02-21 15:42:55,816 INFO org.apache.hadoop.yarn.server.resourcemanager.scheduler.capacity.LeafQueue: Application added - appId: application_1550785279390_0001 user: anushamuppalla, leaf-queue: default #user-pending-applications: 0 #user-active-applications: 1 #queue-pending-applications: 0 #queue-active-applications: 1
2019-02-21 15:42:55,817 INFO org.apache.hadoop.yarn.server.resourcemanager.scheduler.capacity.CapacityScheduler: Added Application Attempt appattempt_1550785279390_0001_000001 to scheduler from user anushamuppalla in queue default
2019-02-21 15:42:55,819 INFO org.apache.hadoop.yarn.server.resourcemanager.rmapp.attempt.RMAppAttemptImpl: appattempt_1550785279390_0001_000001 State change from SUBMITTED to SCHEDULED
2019-02-21 15:42:55,982 INFO org.apache.hadoop.yarn.server.resourcemanager.rmcontainer.RMContainerImpl: container_1550785279390_0001_01_000001 Container Transitioned from NEW to ALLOCATED
2019-02-21 15:42:55,982 INFO org.apache.hadoop.yarn.server.resourcemanager.RMAuditLogger: USER=anushamuppalla	OPERATION=AM Allocated Container	TARGET=SchedulerApp	RESULT=SUCCESS	APPID=application_1550785279390_0001	CONTAINERID=container_1550785279390_0001_01_000001
2019-02-21 15:42:55,983 INFO org.apache.hadoop.yarn.server.resourcemanager.scheduler.SchedulerNode: Assigned container container_1550785279390_0001_01_000001 of capacity <memory:2048, vCores:1> on host anushas-air.kc.umkc.edu:56365, which has 1 containers, <memory:2048, vCores:1> used and <memory:6144, vCores:7> available after allocation
2019-02-21 15:42:55,984 INFO org.apache.hadoop.yarn.server.resourcemanager.scheduler.capacity.allocator.AbstractContainerAllocator: assignedContainer application attempt=appattempt_1550785279390_0001_000001 container=container_1550785279390_0001_01_000001 queue=org.apache.hadoop.yarn.server.resourcemanager.scheduler.capacity.allocator.RegularContainerAllocator@ff53acd clusterResource=<memory:8192, vCores:8> type=OFF_SWITCH
2019-02-21 15:42:56,007 INFO org.apache.hadoop.yarn.server.resourcemanager.security.NMTokenSecretManagerInRM: Sending NMToken for nodeId : anushas-air.kc.umkc.edu:56365 for container : container_1550785279390_0001_01_000001
2019-02-21 15:42:56,018 INFO org.apache.hadoop.yarn.server.resourcemanager.rmcontainer.RMContainerImpl: container_1550785279390_0001_01_000001 Container Transitioned from ALLOCATED to ACQUIRED
2019-02-21 15:42:56,018 INFO org.apache.hadoop.yarn.server.resourcemanager.security.NMTokenSecretManagerInRM: Clear node set for appattempt_1550785279390_0001_000001
2019-02-21 15:42:56,018 INFO org.apache.hadoop.yarn.server.resourcemanager.scheduler.capacity.ParentQueue: Re-sorting assigned queue: root.default stats: default: capacity=1.0, absoluteCapacity=1.0, usedResources=<memory:2048, vCores:1>, usedCapacity=0.25, absoluteUsedCapacity=0.25, numApps=1, numContainers=1
2019-02-21 15:42:56,019 INFO org.apache.hadoop.yarn.server.resourcemanager.rmapp.attempt.RMAppAttemptImpl: Storing attempt: AppId: application_1550785279390_0001 AttemptId: appattempt_1550785279390_0001_000001 MasterContainer: Container: [ContainerId: container_1550785279390_0001_01_000001, Version: 0, NodeId: anushas-air.kc.umkc.edu:56365, NodeHttpAddress: anushas-air.kc.umkc.edu:8042, Resource: <memory:2048, vCores:1>, Priority: 0, Token: Token { kind: ContainerToken, service: 10.205.2.163:56365 }, ]
2019-02-21 15:42:56,019 INFO org.apache.hadoop.yarn.server.resourcemanager.scheduler.capacity.ParentQueue: assignedContainer queue=root usedCapacity=0.25 absoluteUsedCapacity=0.25 used=<memory:2048, vCores:1> cluster=<memory:8192, vCores:8>
2019-02-21 15:42:56,029 INFO org.apache.hadoop.yarn.server.resourcemanager.rmapp.attempt.RMAppAttemptImpl: appattempt_1550785279390_0001_000001 State change from SCHEDULED to ALLOCATED_SAVING
2019-02-21 15:42:56,034 INFO org.apache.hadoop.yarn.server.resourcemanager.rmapp.attempt.RMAppAttemptImpl: appattempt_1550785279390_0001_000001 State change from ALLOCATED_SAVING to ALLOCATED
2019-02-21 15:42:56,036 INFO org.apache.hadoop.yarn.server.resourcemanager.amlauncher.AMLauncher: Launching masterappattempt_1550785279390_0001_000001
2019-02-21 15:42:56,080 INFO org.apache.hadoop.yarn.server.resourcemanager.amlauncher.AMLauncher: Setting up container Container: [ContainerId: container_1550785279390_0001_01_000001, Version: 0, NodeId: anushas-air.kc.umkc.edu:56365, NodeHttpAddress: anushas-air.kc.umkc.edu:8042, Resource: <memory:2048, vCores:1>, Priority: 0, Token: Token { kind: ContainerToken, service: 10.205.2.163:56365 }, ] for AM appattempt_1550785279390_0001_000001
2019-02-21 15:42:56,080 INFO org.apache.hadoop.yarn.server.resourcemanager.security.AMRMTokenSecretManager: Create AMRMToken for ApplicationAttempt: appattempt_1550785279390_0001_000001
2019-02-21 15:42:56,084 INFO org.apache.hadoop.yarn.server.resourcemanager.security.AMRMTokenSecretManager: Creating password for appattempt_1550785279390_0001_000001
2019-02-21 15:42:56,371 INFO org.apache.hadoop.yarn.server.resourcemanager.amlauncher.AMLauncher: Done launching container Container: [ContainerId: container_1550785279390_0001_01_000001, Version: 0, NodeId: anushas-air.kc.umkc.edu:56365, NodeHttpAddress: anushas-air.kc.umkc.edu:8042, Resource: <memory:2048, vCores:1>, Priority: 0, Token: Token { kind: ContainerToken, service: 10.205.2.163:56365 }, ] for AM appattempt_1550785279390_0001_000001
2019-02-21 15:42:56,371 INFO org.apache.hadoop.yarn.server.resourcemanager.rmapp.attempt.RMAppAttemptImpl: appattempt_1550785279390_0001_000001 State change from ALLOCATED to LAUNCHED
2019-02-21 15:42:56,970 INFO org.apache.hadoop.yarn.server.resourcemanager.rmcontainer.RMContainerImpl: container_1550785279390_0001_01_000001 Container Transitioned from ACQUIRED to RUNNING
2019-02-21 15:43:02,047 INFO SecurityLogger.org.apache.hadoop.ipc.Server: Auth successful for appattempt_1550785279390_0001_000001 (auth:SIMPLE)
2019-02-21 15:43:02,054 INFO org.apache.hadoop.yarn.server.resourcemanager.ApplicationMasterService: AM registration appattempt_1550785279390_0001_000001
2019-02-21 15:43:02,055 INFO org.apache.hadoop.yarn.server.resourcemanager.RMAuditLogger: USER=anushamuppalla	IP=127.0.0.1	OPERATION=Register App Master	TARGET=ApplicationMasterService	RESULT=SUCCESS	APPID=application_1550785279390_0001	APPATTEMPTID=appattempt_1550785279390_0001_000001
2019-02-21 15:43:02,055 INFO org.apache.hadoop.yarn.server.resourcemanager.rmapp.attempt.RMAppAttemptImpl: appattempt_1550785279390_0001_000001 State change from LAUNCHED to RUNNING
2019-02-21 15:43:02,055 INFO org.apache.hadoop.yarn.server.resourcemanager.rmapp.RMAppImpl: application_1550785279390_0001 State change from ACCEPTED to RUNNING on event=ATTEMPT_REGISTERED
2019-02-21 15:43:03,991 INFO org.apache.hadoop.yarn.server.resourcemanager.rmcontainer.RMContainerImpl: container_1550785279390_0001_01_000002 Container Transitioned from NEW to ALLOCATED
2019-02-21 15:43:03,991 INFO org.apache.hadoop.yarn.server.resourcemanager.RMAuditLogger: USER=anushamuppalla	OPERATION=AM Allocated Container	TARGET=SchedulerApp	RESULT=SUCCESS	APPID=application_1550785279390_0001	CONTAINERID=container_1550785279390_0001_01_000002
2019-02-21 15:43:03,991 INFO org.apache.hadoop.yarn.server.resourcemanager.scheduler.SchedulerNode: Assigned container container_1550785279390_0001_01_000002 of capacity <memory:1024, vCores:1> on host anushas-air.kc.umkc.edu:56365, which has 2 containers, <memory:3072, vCores:2> used and <memory:5120, vCores:6> available after allocation
2019-02-21 15:43:03,992 INFO org.apache.hadoop.yarn.server.resourcemanager.scheduler.capacity.allocator.AbstractContainerAllocator: assignedContainer application attempt=appattempt_1550785279390_0001_000001 container=container_1550785279390_0001_01_000002 queue=org.apache.hadoop.yarn.server.resourcemanager.scheduler.capacity.allocator.RegularContainerAllocator@ff53acd clusterResource=<memory:8192, vCores:8> type=NODE_LOCAL
2019-02-21 15:43:03,992 INFO org.apache.hadoop.yarn.server.resourcemanager.scheduler.capacity.ParentQueue: Re-sorting assigned queue: root.default stats: default: capacity=1.0, absoluteCapacity=1.0, usedResources=<memory:3072, vCores:2>, usedCapacity=0.375, absoluteUsedCapacity=0.375, numApps=1, numContainers=2
2019-02-21 15:43:03,992 INFO org.apache.hadoop.yarn.server.resourcemanager.scheduler.capacity.ParentQueue: assignedContainer queue=root usedCapacity=0.375 absoluteUsedCapacity=0.375 used=<memory:3072, vCores:2> cluster=<memory:8192, vCores:8>
2019-02-21 15:43:04,131 INFO org.apache.hadoop.yarn.server.resourcemanager.security.NMTokenSecretManagerInRM: Sending NMToken for nodeId : anushas-air.kc.umkc.edu:56365 for container : container_1550785279390_0001_01_000002
2019-02-21 15:43:04,133 INFO org.apache.hadoop.yarn.server.resourcemanager.rmcontainer.RMContainerImpl: container_1550785279390_0001_01_000002 Container Transitioned from ALLOCATED to ACQUIRED
2019-02-21 15:43:04,995 INFO org.apache.hadoop.yarn.server.resourcemanager.rmcontainer.RMContainerImpl: container_1550785279390_0001_01_000002 Container Transitioned from ACQUIRED to RUNNING
2019-02-21 15:43:05,151 INFO org.apache.hadoop.yarn.server.resourcemanager.scheduler.AppSchedulingInfo: checking for deactivate of application :application_1550785279390_0001
2019-02-21 15:43:07,568 INFO org.apache.hadoop.yarn.server.resourcemanager.rmcontainer.RMContainerImpl: container_1550785279390_0001_01_000002 Container Transitioned from RUNNING to COMPLETED
2019-02-21 15:43:07,569 INFO org.apache.hadoop.yarn.server.resourcemanager.RMAuditLogger: USER=anushamuppalla	OPERATION=AM Released Container	TARGET=SchedulerApp	RESULT=SUCCESS	APPID=application_1550785279390_0001	CONTAINERID=container_1550785279390_0001_01_000002
2019-02-21 15:43:07,570 INFO org.apache.hadoop.yarn.server.resourcemanager.scheduler.SchedulerNode: Released container container_1550785279390_0001_01_000002 of capacity <memory:1024, vCores:1> on host anushas-air.kc.umkc.edu:56365, which currently has 1 containers, <memory:2048, vCores:1> used and <memory:6144, vCores:7> available, release resources=true
2019-02-21 15:43:09,578 INFO org.apache.hadoop.yarn.server.resourcemanager.rmcontainer.RMContainerImpl: container_1550785279390_0001_01_000003 Container Transitioned from NEW to ALLOCATED
2019-02-21 15:43:09,578 INFO org.apache.hadoop.yarn.server.resourcemanager.RMAuditLogger: USER=anushamuppalla	OPERATION=AM Allocated Container	TARGET=SchedulerApp	RESULT=SUCCESS	APPID=application_1550785279390_0001	CONTAINERID=container_1550785279390_0001_01_000003
2019-02-21 15:43:09,578 INFO org.apache.hadoop.yarn.server.resourcemanager.scheduler.SchedulerNode: Assigned container container_1550785279390_0001_01_000003 of capacity <memory:1024, vCores:1> on host anushas-air.kc.umkc.edu:56365, which has 2 containers, <memory:3072, vCores:2> used and <memory:5120, vCores:6> available after allocation
2019-02-21 15:43:09,579 INFO org.apache.hadoop.yarn.server.resourcemanager.scheduler.capacity.allocator.AbstractContainerAllocator: assignedContainer application attempt=appattempt_1550785279390_0001_000001 container=container_1550785279390_0001_01_000003 queue=org.apache.hadoop.yarn.server.resourcemanager.scheduler.capacity.allocator.RegularContainerAllocator@ff53acd clusterResource=<memory:8192, vCores:8> type=OFF_SWITCH
2019-02-21 15:43:09,579 INFO org.apache.hadoop.yarn.server.resourcemanager.scheduler.capacity.ParentQueue: Re-sorting assigned queue: root.default stats: default: capacity=1.0, absoluteCapacity=1.0, usedResources=<memory:3072, vCores:2>, usedCapacity=0.375, absoluteUsedCapacity=0.375, numApps=1, numContainers=2
2019-02-21 15:43:09,579 INFO org.apache.hadoop.yarn.server.resourcemanager.scheduler.capacity.ParentQueue: assignedContainer queue=root usedCapacity=0.375 absoluteUsedCapacity=0.375 used=<memory:3072, vCores:2> cluster=<memory:8192, vCores:8>
2019-02-21 15:43:10,196 INFO org.apache.hadoop.yarn.server.resourcemanager.rmcontainer.RMContainerImpl: container_1550785279390_0001_01_000003 Container Transitioned from ALLOCATED to ACQUIRED
2019-02-21 15:43:10,583 INFO org.apache.hadoop.yarn.server.resourcemanager.rmcontainer.RMContainerImpl: container_1550785279390_0001_01_000003 Container Transitioned from ACQUIRED to RUNNING
2019-02-21 15:43:11,203 INFO org.apache.hadoop.yarn.server.resourcemanager.scheduler.AppSchedulingInfo: checking for deactivate of application :application_1550785279390_0001
2019-02-21 15:43:13,744 INFO org.apache.hadoop.yarn.server.resourcemanager.rmcontainer.RMContainerImpl: container_1550785279390_0001_01_000003 Container Transitioned from RUNNING to COMPLETED
2019-02-21 15:43:13,744 INFO org.apache.hadoop.yarn.server.resourcemanager.RMAuditLogger: USER=anushamuppalla	OPERATION=AM Released Container	TARGET=SchedulerApp	RESULT=SUCCESS	APPID=application_1550785279390_0001	CONTAINERID=container_1550785279390_0001_01_000003
2019-02-21 15:43:13,745 INFO org.apache.hadoop.yarn.server.resourcemanager.scheduler.SchedulerNode: Released container container_1550785279390_0001_01_000003 of capacity <memory:1024, vCores:1> on host anushas-air.kc.umkc.edu:56365, which currently has 1 containers, <memory:2048, vCores:1> used and <memory:6144, vCores:7> available, release resources=true
2019-02-21 15:43:14,560 INFO org.apache.hadoop.yarn.server.resourcemanager.rmapp.attempt.RMAppAttemptImpl: Updating application attempt appattempt_1550785279390_0001_000001 with final state: FINISHING, and exit status: -1000
2019-02-21 15:43:14,561 INFO org.apache.hadoop.yarn.server.resourcemanager.rmapp.attempt.RMAppAttemptImpl: appattempt_1550785279390_0001_000001 State change from RUNNING to FINAL_SAVING
2019-02-21 15:43:14,561 INFO org.apache.hadoop.yarn.server.resourcemanager.rmapp.RMAppImpl: Updating application application_1550785279390_0001 with final state: FINISHING
2019-02-21 15:43:14,562 INFO org.apache.hadoop.yarn.server.resourcemanager.rmapp.RMAppImpl: application_1550785279390_0001 State change from RUNNING to FINAL_SAVING on event=ATTEMPT_UNREGISTERED
2019-02-21 15:43:14,562 INFO org.apache.hadoop.yarn.server.resourcemanager.recovery.RMStateStore: Updating info for app: application_1550785279390_0001
2019-02-21 15:43:14,562 INFO org.apache.hadoop.yarn.server.resourcemanager.rmapp.attempt.RMAppAttemptImpl: appattempt_1550785279390_0001_000001 State change from FINAL_SAVING to FINISHING
2019-02-21 15:43:14,562 INFO org.apache.hadoop.yarn.server.resourcemanager.rmapp.RMAppImpl: application_1550785279390_0001 State change from FINAL_SAVING to FINISHING on event=APP_UPDATE_SAVED
2019-02-21 15:43:15,569 INFO org.apache.hadoop.yarn.server.resourcemanager.ApplicationMasterService: application_1550785279390_0001 unregistered successfully. 
2019-02-21 15:43:20,781 INFO org.apache.hadoop.yarn.server.resourcemanager.rmcontainer.RMContainerImpl: container_1550785279390_0001_01_000001 Container Transitioned from RUNNING to COMPLETED
2019-02-21 15:43:20,781 INFO org.apache.hadoop.yarn.server.resourcemanager.ApplicationMasterService: Unregistering app attempt : appattempt_1550785279390_0001_000001
2019-02-21 15:43:20,781 INFO org.apache.hadoop.yarn.server.resourcemanager.RMAuditLogger: USER=anushamuppalla	OPERATION=AM Released Container	TARGET=SchedulerApp	RESULT=SUCCESS	APPID=application_1550785279390_0001	CONTAINERID=container_1550785279390_0001_01_000001
2019-02-21 15:43:20,782 INFO org.apache.hadoop.yarn.server.resourcemanager.scheduler.SchedulerNode: Released container container_1550785279390_0001_01_000001 of capacity <memory:2048, vCores:1> on host anushas-air.kc.umkc.edu:56365, which currently has 0 containers, <memory:0, vCores:0> used and <memory:8192, vCores:8> available, release resources=true
2019-02-21 15:43:20,782 INFO org.apache.hadoop.yarn.server.resourcemanager.security.AMRMTokenSecretManager: Application finished, removing password for appattempt_1550785279390_0001_000001
2019-02-21 15:43:20,782 INFO org.apache.hadoop.yarn.server.resourcemanager.rmapp.attempt.RMAppAttemptImpl: appattempt_1550785279390_0001_000001 State change from FINISHING to FINISHED
2019-02-21 15:43:20,784 INFO org.apache.hadoop.yarn.server.resourcemanager.rmapp.RMAppImpl: application_1550785279390_0001 State change from FINISHING to FINISHED on event=ATTEMPT_FINISHED
2019-02-21 15:43:20,784 INFO org.apache.hadoop.yarn.server.resourcemanager.scheduler.capacity.CapacityScheduler: Application Attempt appattempt_1550785279390_0001_000001 is done. finalState=FINISHED
2019-02-21 15:43:20,785 INFO org.apache.hadoop.yarn.server.resourcemanager.scheduler.AppSchedulingInfo: Application application_1550785279390_0001 requests cleared
2019-02-21 15:43:20,785 INFO org.apache.hadoop.yarn.server.resourcemanager.scheduler.capacity.LeafQueue: Application removed - appId: application_1550785279390_0001 user: anushamuppalla queue: default #user-pending-applications: 0 #user-active-applications: 0 #queue-pending-applications: 0 #queue-active-applications: 0
2019-02-21 15:43:20,785 INFO org.apache.hadoop.yarn.server.resourcemanager.RMAuditLogger: USER=anushamuppalla	OPERATION=Application Finished - Succeeded	TARGET=RMAppManager	RESULT=SUCCESS	APPID=application_1550785279390_0001
2019-02-21 15:43:20,785 INFO org.apache.hadoop.yarn.server.resourcemanager.scheduler.capacity.ParentQueue: Application removed - appId: application_1550785279390_0001 user: anushamuppalla leaf-queue of parent: root #applications: 0
2019-02-21 15:43:20,785 INFO org.apache.hadoop.yarn.server.resourcemanager.amlauncher.AMLauncher: Cleaning master appattempt_1550785279390_0001_000001
2019-02-21 15:43:20,787 INFO org.apache.hadoop.yarn.server.resourcemanager.RMAppManager$ApplicationSummary: appId=application_1550785279390_0001,name=word count,user=anushamuppalla,queue=default,state=FINISHED,trackingUrl=http://anushas-air.kc.umkc.edu:8088/proxy/application_1550785279390_0001/,appMasterHost=anushas-air.kc.umkc.edu,startTime=1550785375700,finishTime=1550785394561,finalStatus=SUCCEEDED,memorySeconds=58719,vcoreSeconds=31,preemptedMemorySeconds=0,preemptedVcoreSeconds=0,preemptedAMContainers=0,preemptedNonAMContainers=0,preemptedResources=<memory:0\, vCores:0>,applicationType=MAPREDUCE
2019-02-21 15:48:05,542 INFO org.apache.hadoop.yarn.server.resourcemanager.ClientRMService: Allocated new applicationId: 2
2019-02-21 15:49:22,627 INFO org.apache.hadoop.yarn.server.resourcemanager.ClientRMService: Allocated new applicationId: 3
2019-02-21 15:49:23,339 INFO org.apache.hadoop.yarn.server.resourcemanager.scheduler.capacity.CapacityScheduler: Application 'application_1550785279390_0003' is submitted without priority hence considering default queue/cluster priority: 0
2019-02-21 15:49:23,339 INFO org.apache.hadoop.yarn.server.resourcemanager.scheduler.capacity.CapacityScheduler: Priority '0' is acceptable in queue : default for application: application_1550785279390_0003 for the user: anushamuppalla
2019-02-21 15:49:23,339 INFO org.apache.hadoop.yarn.server.resourcemanager.ClientRMService: Application with id 3 submitted by user anushamuppalla
2019-02-21 15:49:23,339 INFO org.apache.hadoop.yarn.server.resourcemanager.rmapp.RMAppImpl: Storing application with id application_1550785279390_0003
2019-02-21 15:49:23,339 INFO org.apache.hadoop.yarn.server.resourcemanager.RMAuditLogger: USER=anushamuppalla	IP=127.0.0.1	OPERATION=Submit Application Request	TARGET=ClientRMService	RESULT=SUCCESS	APPID=application_1550785279390_0003
2019-02-21 15:49:23,339 INFO org.apache.hadoop.yarn.server.resourcemanager.rmapp.RMAppImpl: application_1550785279390_0003 State change from NEW to NEW_SAVING on event=START
2019-02-21 15:49:23,339 INFO org.apache.hadoop.yarn.server.resourcemanager.recovery.RMStateStore: Storing info for app: application_1550785279390_0003
2019-02-21 15:49:23,340 INFO org.apache.hadoop.yarn.server.resourcemanager.rmapp.RMAppImpl: application_1550785279390_0003 State change from NEW_SAVING to SUBMITTED on event=APP_NEW_SAVED
2019-02-21 15:49:23,340 INFO org.apache.hadoop.yarn.server.resourcemanager.scheduler.capacity.ParentQueue: Application added - appId: application_1550785279390_0003 user: anushamuppalla leaf-queue of parent: root #applications: 1
2019-02-21 15:49:23,340 INFO org.apache.hadoop.yarn.server.resourcemanager.scheduler.capacity.CapacityScheduler: Accepted application application_1550785279390_0003 from user: anushamuppalla, in queue: default
2019-02-21 15:49:23,343 INFO org.apache.hadoop.yarn.server.resourcemanager.rmapp.RMAppImpl: application_1550785279390_0003 State change from SUBMITTED to ACCEPTED on event=APP_ACCEPTED
2019-02-21 15:49:23,343 INFO org.apache.hadoop.yarn.server.resourcemanager.ApplicationMasterService: Registering app attempt : appattempt_1550785279390_0003_000001
2019-02-21 15:49:23,343 INFO org.apache.hadoop.yarn.server.resourcemanager.rmapp.attempt.RMAppAttemptImpl: appattempt_1550785279390_0003_000001 State change from NEW to SUBMITTED
2019-02-21 15:49:23,343 WARN org.apache.hadoop.yarn.server.resourcemanager.scheduler.capacity.LeafQueue: maximum-am-resource-percent is insufficient to start a single application in queue, it is likely set too low. skipping enforcement to allow at least one application to start
2019-02-21 15:49:23,343 WARN org.apache.hadoop.yarn.server.resourcemanager.scheduler.capacity.LeafQueue: maximum-am-resource-percent is insufficient to start a single application in queue for user, it is likely set too low. skipping enforcement to allow at least one application to start
2019-02-21 15:49:23,344 INFO org.apache.hadoop.yarn.server.resourcemanager.scheduler.capacity.LeafQueue: Application application_1550785279390_0003 from user: anushamuppalla activated in queue: default
2019-02-21 15:49:23,344 INFO org.apache.hadoop.yarn.server.resourcemanager.scheduler.capacity.LeafQueue: Application added - appId: application_1550785279390_0003 user: anushamuppalla, leaf-queue: default #user-pending-applications: 0 #user-active-applications: 1 #queue-pending-applications: 0 #queue-active-applications: 1
2019-02-21 15:49:23,344 INFO org.apache.hadoop.yarn.server.resourcemanager.scheduler.capacity.CapacityScheduler: Added Application Attempt appattempt_1550785279390_0003_000001 to scheduler from user anushamuppalla in queue default
2019-02-21 15:49:23,345 INFO org.apache.hadoop.yarn.server.resourcemanager.rmapp.attempt.RMAppAttemptImpl: appattempt_1550785279390_0003_000001 State change from SUBMITTED to SCHEDULED
2019-02-21 15:49:23,661 INFO org.apache.hadoop.yarn.server.resourcemanager.rmcontainer.RMContainerImpl: container_1550785279390_0003_01_000001 Container Transitioned from NEW to ALLOCATED
2019-02-21 15:49:23,661 INFO org.apache.hadoop.yarn.server.resourcemanager.RMAuditLogger: USER=anushamuppalla	OPERATION=AM Allocated Container	TARGET=SchedulerApp	RESULT=SUCCESS	APPID=application_1550785279390_0003	CONTAINERID=container_1550785279390_0003_01_000001
2019-02-21 15:49:23,661 INFO org.apache.hadoop.yarn.server.resourcemanager.scheduler.SchedulerNode: Assigned container container_1550785279390_0003_01_000001 of capacity <memory:2048, vCores:1> on host anushas-air.kc.umkc.edu:56365, which has 1 containers, <memory:2048, vCores:1> used and <memory:6144, vCores:7> available after allocation
2019-02-21 15:49:23,661 INFO org.apache.hadoop.yarn.server.resourcemanager.scheduler.capacity.allocator.AbstractContainerAllocator: assignedContainer application attempt=appattempt_1550785279390_0003_000001 container=container_1550785279390_0003_01_000001 queue=org.apache.hadoop.yarn.server.resourcemanager.scheduler.capacity.allocator.RegularContainerAllocator@45730ae1 clusterResource=<memory:8192, vCores:8> type=OFF_SWITCH
2019-02-21 15:49:23,668 INFO org.apache.hadoop.yarn.server.resourcemanager.security.NMTokenSecretManagerInRM: Sending NMToken for nodeId : anushas-air.kc.umkc.edu:56365 for container : container_1550785279390_0003_01_000001
2019-02-21 15:49:23,669 INFO org.apache.hadoop.yarn.server.resourcemanager.rmcontainer.RMContainerImpl: container_1550785279390_0003_01_000001 Container Transitioned from ALLOCATED to ACQUIRED
2019-02-21 15:49:23,670 INFO org.apache.hadoop.yarn.server.resourcemanager.security.NMTokenSecretManagerInRM: Clear node set for appattempt_1550785279390_0003_000001
2019-02-21 15:49:23,670 INFO org.apache.hadoop.yarn.server.resourcemanager.rmapp.attempt.RMAppAttemptImpl: Storing attempt: AppId: application_1550785279390_0003 AttemptId: appattempt_1550785279390_0003_000001 MasterContainer: Container: [ContainerId: container_1550785279390_0003_01_000001, Version: 0, NodeId: anushas-air.kc.umkc.edu:56365, NodeHttpAddress: anushas-air.kc.umkc.edu:8042, Resource: <memory:2048, vCores:1>, Priority: 0, Token: Token { kind: ContainerToken, service: 10.205.2.163:56365 }, ]
2019-02-21 15:49:23,670 INFO org.apache.hadoop.yarn.server.resourcemanager.scheduler.capacity.ParentQueue: Re-sorting assigned queue: root.default stats: default: capacity=1.0, absoluteCapacity=1.0, usedResources=<memory:2048, vCores:1>, usedCapacity=0.25, absoluteUsedCapacity=0.25, numApps=1, numContainers=1
2019-02-21 15:49:23,670 INFO org.apache.hadoop.yarn.server.resourcemanager.scheduler.capacity.ParentQueue: assignedContainer queue=root usedCapacity=0.25 absoluteUsedCapacity=0.25 used=<memory:2048, vCores:1> cluster=<memory:8192, vCores:8>
2019-02-21 15:49:23,670 INFO org.apache.hadoop.yarn.server.resourcemanager.rmapp.attempt.RMAppAttemptImpl: appattempt_1550785279390_0003_000001 State change from SCHEDULED to ALLOCATED_SAVING
2019-02-21 15:49:23,671 INFO org.apache.hadoop.yarn.server.resourcemanager.rmapp.attempt.RMAppAttemptImpl: appattempt_1550785279390_0003_000001 State change from ALLOCATED_SAVING to ALLOCATED
2019-02-21 15:49:23,671 INFO org.apache.hadoop.yarn.server.resourcemanager.amlauncher.AMLauncher: Launching masterappattempt_1550785279390_0003_000001
2019-02-21 15:49:23,675 INFO org.apache.hadoop.yarn.server.resourcemanager.amlauncher.AMLauncher: Setting up container Container: [ContainerId: container_1550785279390_0003_01_000001, Version: 0, NodeId: anushas-air.kc.umkc.edu:56365, NodeHttpAddress: anushas-air.kc.umkc.edu:8042, Resource: <memory:2048, vCores:1>, Priority: 0, Token: Token { kind: ContainerToken, service: 10.205.2.163:56365 }, ] for AM appattempt_1550785279390_0003_000001
2019-02-21 15:49:23,675 INFO org.apache.hadoop.yarn.server.resourcemanager.security.AMRMTokenSecretManager: Create AMRMToken for ApplicationAttempt: appattempt_1550785279390_0003_000001
2019-02-21 15:49:23,675 INFO org.apache.hadoop.yarn.server.resourcemanager.security.AMRMTokenSecretManager: Creating password for appattempt_1550785279390_0003_000001
2019-02-21 15:49:23,688 INFO org.apache.hadoop.yarn.server.resourcemanager.amlauncher.AMLauncher: Done launching container Container: [ContainerId: container_1550785279390_0003_01_000001, Version: 0, NodeId: anushas-air.kc.umkc.edu:56365, NodeHttpAddress: anushas-air.kc.umkc.edu:8042, Resource: <memory:2048, vCores:1>, Priority: 0, Token: Token { kind: ContainerToken, service: 10.205.2.163:56365 }, ] for AM appattempt_1550785279390_0003_000001
2019-02-21 15:49:23,688 INFO org.apache.hadoop.yarn.server.resourcemanager.rmapp.attempt.RMAppAttemptImpl: appattempt_1550785279390_0003_000001 State change from ALLOCATED to LAUNCHED
2019-02-21 15:49:24,667 INFO org.apache.hadoop.yarn.server.resourcemanager.rmcontainer.RMContainerImpl: container_1550785279390_0003_01_000001 Container Transitioned from ACQUIRED to RUNNING
2019-02-21 15:49:28,182 INFO SecurityLogger.org.apache.hadoop.ipc.Server: Auth successful for appattempt_1550785279390_0003_000001 (auth:SIMPLE)
2019-02-21 15:49:28,187 INFO org.apache.hadoop.yarn.server.resourcemanager.ApplicationMasterService: AM registration appattempt_1550785279390_0003_000001
2019-02-21 15:49:28,187 INFO org.apache.hadoop.yarn.server.resourcemanager.RMAuditLogger: USER=anushamuppalla	IP=127.0.0.1	OPERATION=Register App Master	TARGET=ApplicationMasterService	RESULT=SUCCESS	APPID=application_1550785279390_0003	APPATTEMPTID=appattempt_1550785279390_0003_000001
2019-02-21 15:49:28,187 INFO org.apache.hadoop.yarn.server.resourcemanager.rmapp.attempt.RMAppAttemptImpl: appattempt_1550785279390_0003_000001 State change from LAUNCHED to RUNNING
2019-02-21 15:49:28,187 INFO org.apache.hadoop.yarn.server.resourcemanager.rmapp.RMAppImpl: application_1550785279390_0003 State change from ACCEPTED to RUNNING on event=ATTEMPT_REGISTERED
2019-02-21 15:49:29,686 INFO org.apache.hadoop.yarn.server.resourcemanager.rmcontainer.RMContainerImpl: container_1550785279390_0003_01_000002 Container Transitioned from NEW to ALLOCATED
2019-02-21 15:49:29,686 INFO org.apache.hadoop.yarn.server.resourcemanager.RMAuditLogger: USER=anushamuppalla	OPERATION=AM Allocated Container	TARGET=SchedulerApp	RESULT=SUCCESS	APPID=application_1550785279390_0003	CONTAINERID=container_1550785279390_0003_01_000002
2019-02-21 15:49:29,686 INFO org.apache.hadoop.yarn.server.resourcemanager.scheduler.SchedulerNode: Assigned container container_1550785279390_0003_01_000002 of capacity <memory:1024, vCores:1> on host anushas-air.kc.umkc.edu:56365, which has 2 containers, <memory:3072, vCores:2> used and <memory:5120, vCores:6> available after allocation
2019-02-21 15:49:29,686 INFO org.apache.hadoop.yarn.server.resourcemanager.scheduler.capacity.allocator.AbstractContainerAllocator: assignedContainer application attempt=appattempt_1550785279390_0003_000001 container=container_1550785279390_0003_01_000002 queue=org.apache.hadoop.yarn.server.resourcemanager.scheduler.capacity.allocator.RegularContainerAllocator@45730ae1 clusterResource=<memory:8192, vCores:8> type=NODE_LOCAL
2019-02-21 15:49:29,687 INFO org.apache.hadoop.yarn.server.resourcemanager.scheduler.capacity.ParentQueue: Re-sorting assigned queue: root.default stats: default: capacity=1.0, absoluteCapacity=1.0, usedResources=<memory:3072, vCores:2>, usedCapacity=0.375, absoluteUsedCapacity=0.375, numApps=1, numContainers=2
2019-02-21 15:49:29,687 INFO org.apache.hadoop.yarn.server.resourcemanager.scheduler.capacity.ParentQueue: assignedContainer queue=root usedCapacity=0.375 absoluteUsedCapacity=0.375 used=<memory:3072, vCores:2> cluster=<memory:8192, vCores:8>
2019-02-21 15:49:30,253 INFO org.apache.hadoop.yarn.server.resourcemanager.security.NMTokenSecretManagerInRM: Sending NMToken for nodeId : anushas-air.kc.umkc.edu:56365 for container : container_1550785279390_0003_01_000002
2019-02-21 15:49:30,255 INFO org.apache.hadoop.yarn.server.resourcemanager.rmcontainer.RMContainerImpl: container_1550785279390_0003_01_000002 Container Transitioned from ALLOCATED to ACQUIRED
2019-02-21 15:49:30,687 INFO org.apache.hadoop.yarn.server.resourcemanager.rmcontainer.RMContainerImpl: container_1550785279390_0003_01_000002 Container Transitioned from ACQUIRED to RUNNING
2019-02-21 15:49:31,271 INFO org.apache.hadoop.yarn.server.resourcemanager.scheduler.AppSchedulingInfo: checking for deactivate of application :application_1550785279390_0003
2019-02-21 15:49:34,208 INFO org.apache.hadoop.yarn.server.resourcemanager.rmcontainer.RMContainerImpl: container_1550785279390_0003_01_000002 Container Transitioned from RUNNING to COMPLETED
2019-02-21 15:49:34,209 INFO org.apache.hadoop.yarn.server.resourcemanager.RMAuditLogger: USER=anushamuppalla	OPERATION=AM Released Container	TARGET=SchedulerApp	RESULT=SUCCESS	APPID=application_1550785279390_0003	CONTAINERID=container_1550785279390_0003_01_000002
2019-02-21 15:49:34,209 INFO org.apache.hadoop.yarn.server.resourcemanager.scheduler.SchedulerNode: Released container container_1550785279390_0003_01_000002 of capacity <memory:1024, vCores:1> on host anushas-air.kc.umkc.edu:56365, which currently has 1 containers, <memory:2048, vCores:1> used and <memory:6144, vCores:7> available, release resources=true
2019-02-21 15:49:36,223 INFO org.apache.hadoop.yarn.server.resourcemanager.rmcontainer.RMContainerImpl: container_1550785279390_0003_01_000003 Container Transitioned from NEW to ALLOCATED
2019-02-21 15:49:36,223 INFO org.apache.hadoop.yarn.server.resourcemanager.RMAuditLogger: USER=anushamuppalla	OPERATION=AM Allocated Container	TARGET=SchedulerApp	RESULT=SUCCESS	APPID=application_1550785279390_0003	CONTAINERID=container_1550785279390_0003_01_000003
2019-02-21 15:49:36,224 INFO org.apache.hadoop.yarn.server.resourcemanager.scheduler.SchedulerNode: Assigned container container_1550785279390_0003_01_000003 of capacity <memory:1024, vCores:1> on host anushas-air.kc.umkc.edu:56365, which has 2 containers, <memory:3072, vCores:2> used and <memory:5120, vCores:6> available after allocation
2019-02-21 15:49:36,224 INFO org.apache.hadoop.yarn.server.resourcemanager.scheduler.capacity.allocator.AbstractContainerAllocator: assignedContainer application attempt=appattempt_1550785279390_0003_000001 container=container_1550785279390_0003_01_000003 queue=org.apache.hadoop.yarn.server.resourcemanager.scheduler.capacity.allocator.RegularContainerAllocator@45730ae1 clusterResource=<memory:8192, vCores:8> type=OFF_SWITCH
2019-02-21 15:49:36,224 INFO org.apache.hadoop.yarn.server.resourcemanager.scheduler.capacity.ParentQueue: Re-sorting assigned queue: root.default stats: default: capacity=1.0, absoluteCapacity=1.0, usedResources=<memory:3072, vCores:2>, usedCapacity=0.375, absoluteUsedCapacity=0.375, numApps=1, numContainers=2
2019-02-21 15:49:36,225 INFO org.apache.hadoop.yarn.server.resourcemanager.scheduler.capacity.ParentQueue: assignedContainer queue=root usedCapacity=0.375 absoluteUsedCapacity=0.375 used=<memory:3072, vCores:2> cluster=<memory:8192, vCores:8>
2019-02-21 15:49:36,316 INFO org.apache.hadoop.yarn.server.resourcemanager.rmcontainer.RMContainerImpl: container_1550785279390_0003_01_000003 Container Transitioned from ALLOCATED to ACQUIRED
2019-02-21 15:49:37,225 INFO org.apache.hadoop.yarn.server.resourcemanager.rmcontainer.RMContainerImpl: container_1550785279390_0003_01_000003 Container Transitioned from ACQUIRED to RUNNING
2019-02-21 15:49:37,338 INFO org.apache.hadoop.yarn.server.resourcemanager.scheduler.AppSchedulingInfo: checking for deactivate of application :application_1550785279390_0003
2019-02-21 15:49:39,689 INFO org.apache.hadoop.yarn.server.resourcemanager.rmcontainer.RMContainerImpl: container_1550785279390_0003_01_000003 Container Transitioned from RUNNING to COMPLETED
2019-02-21 15:49:39,689 INFO org.apache.hadoop.yarn.server.resourcemanager.RMAuditLogger: USER=anushamuppalla	OPERATION=AM Released Container	TARGET=SchedulerApp	RESULT=SUCCESS	APPID=application_1550785279390_0003	CONTAINERID=container_1550785279390_0003_01_000003
2019-02-21 15:49:39,689 INFO org.apache.hadoop.yarn.server.resourcemanager.scheduler.SchedulerNode: Released container container_1550785279390_0003_01_000003 of capacity <memory:1024, vCores:1> on host anushas-air.kc.umkc.edu:56365, which currently has 1 containers, <memory:2048, vCores:1> used and <memory:6144, vCores:7> available, release resources=true
2019-02-21 15:49:40,093 INFO org.apache.hadoop.yarn.server.resourcemanager.rmapp.attempt.RMAppAttemptImpl: Updating application attempt appattempt_1550785279390_0003_000001 with final state: FINISHING, and exit status: -1000
2019-02-21 15:49:40,093 INFO org.apache.hadoop.yarn.server.resourcemanager.rmapp.attempt.RMAppAttemptImpl: appattempt_1550785279390_0003_000001 State change from RUNNING to FINAL_SAVING
2019-02-21 15:49:40,093 INFO org.apache.hadoop.yarn.server.resourcemanager.rmapp.RMAppImpl: Updating application application_1550785279390_0003 with final state: FINISHING
2019-02-21 15:49:40,093 INFO org.apache.hadoop.yarn.server.resourcemanager.rmapp.RMAppImpl: application_1550785279390_0003 State change from RUNNING to FINAL_SAVING on event=ATTEMPT_UNREGISTERED
2019-02-21 15:49:40,093 INFO org.apache.hadoop.yarn.server.resourcemanager.recovery.RMStateStore: Updating info for app: application_1550785279390_0003
2019-02-21 15:49:40,093 INFO org.apache.hadoop.yarn.server.resourcemanager.rmapp.attempt.RMAppAttemptImpl: appattempt_1550785279390_0003_000001 State change from FINAL_SAVING to FINISHING
2019-02-21 15:49:40,093 INFO org.apache.hadoop.yarn.server.resourcemanager.rmapp.RMAppImpl: application_1550785279390_0003 State change from FINAL_SAVING to FINISHING on event=APP_UPDATE_SAVED
2019-02-21 15:49:41,097 INFO org.apache.hadoop.yarn.server.resourcemanager.ApplicationMasterService: application_1550785279390_0003 unregistered successfully. 
2019-02-21 15:49:46,328 INFO org.apache.hadoop.yarn.server.resourcemanager.rmcontainer.RMContainerImpl: container_1550785279390_0003_01_000001 Container Transitioned from RUNNING to COMPLETED
2019-02-21 15:49:46,328 INFO org.apache.hadoop.yarn.server.resourcemanager.ApplicationMasterService: Unregistering app attempt : appattempt_1550785279390_0003_000001
2019-02-21 15:49:46,328 INFO org.apache.hadoop.yarn.server.resourcemanager.RMAuditLogger: USER=anushamuppalla	OPERATION=AM Released Container	TARGET=SchedulerApp	RESULT=SUCCESS	APPID=application_1550785279390_0003	CONTAINERID=container_1550785279390_0003_01_000001
2019-02-21 15:49:46,328 INFO org.apache.hadoop.yarn.server.resourcemanager.scheduler.SchedulerNode: Released container container_1550785279390_0003_01_000001 of capacity <memory:2048, vCores:1> on host anushas-air.kc.umkc.edu:56365, which currently has 0 containers, <memory:0, vCores:0> used and <memory:8192, vCores:8> available, release resources=true
2019-02-21 15:49:46,328 INFO org.apache.hadoop.yarn.server.resourcemanager.security.AMRMTokenSecretManager: Application finished, removing password for appattempt_1550785279390_0003_000001
2019-02-21 15:49:46,328 INFO org.apache.hadoop.yarn.server.resourcemanager.rmapp.attempt.RMAppAttemptImpl: appattempt_1550785279390_0003_000001 State change from FINISHING to FINISHED
2019-02-21 15:49:46,328 INFO org.apache.hadoop.yarn.server.resourcemanager.rmapp.RMAppImpl: application_1550785279390_0003 State change from FINISHING to FINISHED on event=ATTEMPT_FINISHED
2019-02-21 15:49:46,329 INFO org.apache.hadoop.yarn.server.resourcemanager.scheduler.capacity.CapacityScheduler: Application Attempt appattempt_1550785279390_0003_000001 is done. finalState=FINISHED
2019-02-21 15:49:46,329 INFO org.apache.hadoop.yarn.server.resourcemanager.RMAuditLogger: USER=anushamuppalla	OPERATION=Application Finished - Succeeded	TARGET=RMAppManager	RESULT=SUCCESS	APPID=application_1550785279390_0003
2019-02-21 15:49:46,329 INFO org.apache.hadoop.yarn.server.resourcemanager.scheduler.AppSchedulingInfo: Application application_1550785279390_0003 requests cleared
2019-02-21 15:49:46,329 INFO org.apache.hadoop.yarn.server.resourcemanager.amlauncher.AMLauncher: Cleaning master appattempt_1550785279390_0003_000001
2019-02-21 15:49:46,330 INFO org.apache.hadoop.yarn.server.resourcemanager.scheduler.capacity.LeafQueue: Application removed - appId: application_1550785279390_0003 user: anushamuppalla queue: default #user-pending-applications: 0 #user-active-applications: 0 #queue-pending-applications: 0 #queue-active-applications: 0
2019-02-21 15:49:46,330 INFO org.apache.hadoop.yarn.server.resourcemanager.scheduler.capacity.ParentQueue: Application removed - appId: application_1550785279390_0003 user: anushamuppalla leaf-queue of parent: root #applications: 0
2019-02-21 15:49:46,330 INFO org.apache.hadoop.yarn.server.resourcemanager.RMAppManager$ApplicationSummary: appId=application_1550785279390_0003,name=word count,user=anushamuppalla,queue=default,state=FINISHED,trackingUrl=http://anushas-air.kc.umkc.edu:8088/proxy/application_1550785279390_0003/,appMasterHost=anushas-air.kc.umkc.edu,startTime=1550785763339,finishTime=1550785780093,finalStatus=SUCCEEDED,memorySeconds=54602,vcoreSeconds=29,preemptedMemorySeconds=0,preemptedVcoreSeconds=0,preemptedAMContainers=0,preemptedNonAMContainers=0,preemptedResources=<memory:0\, vCores:0>,applicationType=MAPREDUCE
2019-02-21 15:49:48,337 INFO org.apache.hadoop.yarn.server.resourcemanager.scheduler.AbstractYarnScheduler: Container container_1550785279390_0003_01_000003 completed with event FINISHED, but corresponding RMContainer doesn't exist.
2019-02-21 15:51:19,245 INFO org.apache.hadoop.yarn.server.resourcemanager.scheduler.AbstractYarnScheduler: Release request cache is cleaned up
2019-02-21 16:06:20,178 INFO org.apache.hadoop.util.JvmPauseMonitor: Detected pause in JVM or host machine (eg GC): pause of approximately 1118ms
No GCs detected
2019-02-21 16:10:25,474 INFO org.apache.hadoop.util.JvmPauseMonitor: Detected pause in JVM or host machine (eg GC): pause of approximately 1016ms
No GCs detected
2019-02-21 16:14:00,527 INFO org.apache.hadoop.util.JvmPauseMonitor: Detected pause in JVM or host machine (eg GC): pause of approximately 1266ms
No GCs detected
2019-02-21 16:16:24,825 INFO org.apache.hadoop.util.JvmPauseMonitor: Detected pause in JVM or host machine (eg GC): pause of approximately 1261ms
No GCs detected
2019-02-21 16:18:18,239 INFO org.apache.hadoop.util.JvmPauseMonitor: Detected pause in JVM or host machine (eg GC): pause of approximately 1054ms
No GCs detected
2019-02-21 16:44:04,759 INFO org.apache.hadoop.util.JvmPauseMonitor: Detected pause in JVM or host machine (eg GC): pause of approximately 1053ms
No GCs detected
2019-02-21 18:34:33,037 INFO org.apache.hadoop.util.JvmPauseMonitor: Detected pause in JVM or host machine (eg GC): pause of approximately 1245ms
No GCs detected
2019-02-21 18:35:50,029 INFO org.apache.hadoop.util.JvmPauseMonitor: Detected pause in JVM or host machine (eg GC): pause of approximately 1014ms
No GCs detected
2019-02-21 23:14:47,828 INFO org.apache.hadoop.util.JvmPauseMonitor: Detected pause in JVM or host machine (eg GC): pause of approximately 1224ms
No GCs detected
2019-02-22 03:15:34,949 INFO org.apache.hadoop.util.JvmPauseMonitor: Detected pause in JVM or host machine (eg GC): pause of approximately 1241ms
No GCs detected
2019-02-22 05:15:49,048 INFO org.apache.hadoop.util.JvmPauseMonitor: Detected pause in JVM or host machine (eg GC): pause of approximately 1244ms
No GCs detected
2019-02-22 07:16:03,159 INFO org.apache.hadoop.util.JvmPauseMonitor: Detected pause in JVM or host machine (eg GC): pause of approximately 1226ms
No GCs detected
2019-02-22 09:01:02,396 INFO org.apache.hadoop.util.JvmPauseMonitor: Detected pause in JVM or host machine (eg GC): pause of approximately 1171ms
No GCs detected
2019-02-22 09:06:15,376 INFO org.apache.hadoop.util.JvmPauseMonitor: Detected pause in JVM or host machine (eg GC): pause of approximately 1046ms
No GCs detected
2019-02-22 09:07:22,567 INFO org.apache.hadoop.util.JvmPauseMonitor: Detected pause in JVM or host machine (eg GC): pause of approximately 1042ms
No GCs detected
2019-02-22 09:12:12,847 INFO org.apache.hadoop.util.JvmPauseMonitor: Detected pause in JVM or host machine (eg GC): pause of approximately 1080ms
No GCs detected
2019-02-22 09:29:25,630 INFO org.apache.hadoop.util.JvmPauseMonitor: Detected pause in JVM or host machine (eg GC): pause of approximately 1157ms
No GCs detected
2019-02-22 09:39:38,754 INFO org.apache.hadoop.util.JvmPauseMonitor: Detected pause in JVM or host machine (eg GC): pause of approximately 1035ms
No GCs detected
2019-02-22 09:57:43,173 INFO org.apache.hadoop.util.JvmPauseMonitor: Detected pause in JVM or host machine (eg GC): pause of approximately 1217ms
No GCs detected
2019-02-22 10:01:14,546 INFO org.apache.hadoop.util.JvmPauseMonitor: Detected pause in JVM or host machine (eg GC): pause of approximately 1202ms
No GCs detected
2019-02-22 10:26:18,493 INFO org.apache.hadoop.util.JvmPauseMonitor: Detected pause in JVM or host machine (eg GC): pause of approximately 1083ms
No GCs detected
2019-02-22 10:30:32,896 INFO org.apache.hadoop.util.JvmPauseMonitor: Detected pause in JVM or host machine (eg GC): pause of approximately 1152ms
No GCs detected
2019-02-22 11:01:25,581 INFO org.apache.hadoop.util.JvmPauseMonitor: Detected pause in JVM or host machine (eg GC): pause of approximately 1179ms
No GCs detected
2019-02-22 11:32:53,207 INFO org.apache.hadoop.util.JvmPauseMonitor: Detected pause in JVM or host machine (eg GC): pause of approximately 1118ms
No GCs detected
